Workbook

Sheet TONG QUAN
B2: BẢNG CHẤM CÔNG NHÂN VIÊN
B4: Tháng 06/2026 - Công ty TNHH (theo dữ liặu hệ thống HRM)
B7: NỘI DUNG FILE
B8: 1. DM_NHAN_VIEN | C8: Danh mục nhân viên: mã NV, họ tên, phòng ban, chức vụ, ca làm chính, ngày vào làm (tương ứng bảng users / employee_profiles / departments / positions trong database).
B9: 2. DM_CA_LAM | C9: Danh mục ca làm việc: giờ vào/ra chuẩn, giờ nghỉ giữa ca, hệ số lương ca (tương ứng bảng shifts).
B10: 3. CHI_TIET_CHAM_CONG | C10: Bảng chấm công CHI TIẾT theo từng ngày / từng nhân viên: giờ vào - ra thực tế, số phút đi muộn / về sớm, số giờ công, trạng thái, giờ OT, lý do OT, ghi chú (tương ứng bảng attendance).
B11: 4. BANG_CONG_THANG | C11: Bảng CÔNG tổng hợp theo tháng (dạng bảng chấm công truyền thống): mỗi dòng là 1 nhân viên, mỗi cột là 1 ngày trong tháng, tự đổ mã trạng thái và tổng hợp công bằng công thức từ sheet chi tiết.
B12: 5. DM_TRANG_THAI | C12: Giải thích mã trạng thái dùng trong bảng công (P, L, A, NP, KL, CN).
B14: LưU Ý | C14: Tất cả các cột tổng hợp (số công, số ngày muộn, số ngày vắng, tổng giờ OT...) đều dùng công thức Excel (COUNTIF/SUMIFS/VLOOKUP) tham chiều trực tiếp từ sheet CHI_TIET_CHAM_CONG và DM_NHAN_VIEN, nên khi sửa dụ liệu chi tiết (giờ vào/ra, trạng thái...) các bảng tổng hợp sẽ tự cập nhật.

Sheet DM_NHAN_VIEN
A1: DANH MỤC NHÂN VIÊN
A2: Tương ứng bảng: users + employee_profiles + departments + positions
A3: STT | B3: Mã NV | C3: Họ và tên | D3: Phòng ban | E3: Chức vụ | F3: Ca làm chính | G3: Ngày vào làm
A4: 1 | B4: NV002 | C4: Nguyễn Văn Giám Đốc | D4: Hành chính | E4: Giám đốc | F4: Ca Hành Chính | G4: 2020-01-01
A5: 2 | B5: NV003 | C5: Trần Thị Nhân Sự | D5: Nhân sự | E5: Trưởng phòng | F5: Ca Hành Chính | G5: 2021-03-10
A6: 3 | B6: NV004 | C6: Lê Văn Quản Đốc | D6: Xưởng sản xuất | E6: Quản đốc | F6: Ca Hành Chính | G6: 2020-06-01
A7: 4 | B7: NV005 | C7: Phạm Công Nhân | D7: Xưởng sản xuất | E7: Công nhân | F7: Ca Hành Chính | G7: 2022-02-15
A8: 5 | B8: NV006 | C8: Đỗ Thị Hà | D8: Hành chính | E8: Trưởng phòng | F8: Ca Hành Chính | G8: 2018-03-01
A9: 6 | B9: NV007 | C9: Ngô Văn Tài | D9: Hành chính | E9: Phó phòng | F9: Ca Hành Chính | G9: 2020-05-01
A10: 7 | B10: NV008 | C10: Vũ Thị Nga | D10: Hành chính | E10: Chuyên viên | F10: Ca Hành Chính | G10: 2021-01-10
A11: 8 | B11: NV010 | C11: Đặng Thị Hồng | D11: Nhân sự | E11: Chuyên viên | F11: Ca Hành Chính | G11: 2021-06-01
A12: 9 | B12: NV011 | C12: Chu Văn Minh | D12: Nhân sự | E12: Chuyên viên | F12: Ca Hành Chính | G12: 2021-07-01
A13: 10 | B13: NV014 | C13: Phan Thị Khánh | D13: Kế toán | E13: Trưởng phòng | F13: Ca Hành Chính | G13: 2019-02-01
A14: 11 | B14: NV015 | C14: Trịnh Văn Hùng | D14: Kế toán | E14: Phó phòng | F14: Ca Hành Chính | G14: 2020-04-01
A15: 12 | B15: NV019 | C15: Hoàng Văn Lộc | D15: Kinh doanh | E15: Trưởng phòng | F15: Ca Hành Chính | G15: 2019-09-01
... A18: 15 | B18: NV030 | C18: Tống Văn Thắng | D18: Xưởng sản xuất | E18: Tổ trưởng | F18: Ca Hành Chính | G18: 2019-05-01

Sheet DM_CA_LAM
A1: DANH MỤC CA LÀM VIỆC
A2: Tương ứng bảng: shifts
A3: Ca làm việc | B3: Giờ vào chuẩn | C3: Giờ ra chuẩn | D3: Nghỉ giởa ca (từ) | E3: Nghỉ giởa ca (đến) | F3: Số giờ làm chuẩn | G3: Hệ số lương ca
A4: Ca Hành Chính | B4: 07:30 | C4: 17:30 | D4: 11:00 | E4: 13:00 | F4: =(TIMEVALUE(C4)-TIMEVALUE(B4))*24-(TIMEVALUE(E4)-TIMEVALUE(D4))*24 -> 8 | G4: 1
A5: Ca Đêm 1 | B5: 18:00 | C5: 20:00 | F5: =(TIMEVALUE(C5)-TIMEVALUE(B5))*24 -> 2 | G5: 1.5
A6: Ca Đêm 2 | B6: 18:00 | C6: 22:00 | D6: 20:00 | E6: 20:30 | F6: =(TIMEVALUE(C6)-TIMEVALUE(B6))*24-(TIMEVALUE(E6)-TIMEVALUE(D6))*24 -> 3.5 | G6: 1.5

Sheet DM_TRANG_THAI
A1: DANH MỤC TRẮNG THÁI CHẤM CÔNG
A2: Mã dùng trong sheet BANG_CONG_THANG
A3: Trạng thái (chi tiết) | B3: Mã (bảng công) | C3: Diễn giải | D3: Màu
A4: Đi làm đủ công | B4: P | C4: Nhân viên đi làm đầy đủ, đúng giờ | D4: P
A5: Đi muộn | B5: L | C5: Nhân viên đi làm nhưng vào trễ hơn giờ chuẩn | D5: L
A6: Vắng không lý do | B6: A | C6: Nhân viên nghỉ không phép, không báo trước | D6: A
A7: Nghỉ phép năm | B7: NP | C7: Nghỉ theo chế độ phép năm, vẫn hưởng lương | D7: NP
A8: Nghỉ không lương | B8: KL | C8: Nghỉ không hưởng lương | D8: KL
A9: Ngày nghỉ theo lịch | B9: CN | C9: Ngày nghỉ theo lịch (Chủ Nhật) - không phải ngày công | D9: CN

Sheet CHI_TIET_CHAM_CONG
A1: BẢNG CHẤM CÔNG CHI TIẾT - THÁNG 06/2026
A2: Tương ứng bảng: attendance (user_id, shift_id, work_date, check_in, check_out, status, overtime_hrs, ot_reason)
A3: STT | B3: Mã NV | C3: Họ và tên | D3: Phòng ban | E3: Chức vụ | F3: Ngày | G3: Thứ | H3: Ca làm | I3: Giờ vào chuẩn | J3: Giờ ra chuẩn | K3: Giờ vào thực tế | L3: Giờ ra thực tế | M3: Đi muộn (phút) | N3: Về sớm (phút) | O3: Số giờ công | P3: Trạng thái | Q3: Giờ OT | R3: Lý do OT | S3: Ghi chú | T3: _KEY | U3: _MA_CODE
A4: 1 | B4: NV002 | C4: =VLOOKUP($B4,DM_NHAN_VIEN!$B$4:$F$18,2,FALSE()) -> Nguyễn Văn Giám Đốc | D4: =VLOOKUP($B4,DM_NHAN_VIEN!$B$4:$F$18,3,FALSE()) -> Hành chính | E4: =VLOOKUP($B4,DM_NHAN_VIEN!$B$4:$F$18,4,FALSE()) -> Giám đốc | F4: 46174 | G4: =CHOOSE(WEEKDAY(F4,2),"Thứ Hai","Thứ Ba","Thứ Tư","Thứ Năm","Thứ Sáu","Thứ Bảy","Chủ Nhật") -> Thứ Hai | H4: =VLOOKUP($B4,DM_NHAN_VIEN!$B$4:$F$18,5,FALSE()) -> Ca Hành Chính | I4: =VLOOKUP($H4,DM_CA_LAM!$A$4:$C$6,2,FALSE()) -> 07:30 | J4: =VLOOKUP($H4,DM_CA_LAM!$A$4:$C$6,3,FALSE()) -> 17:30 | K4: 07:20 | L4: 17:38 | M4: =IF($K4="","",MAX(0,ROUND((TIMEVALUE($K4)-TIMEVALUE($I4))*1440,0))) -> 0 | N4: =IF($L4="","",MAX(0,ROUND((TIMEVALUE($J4)-TIMEVALUE($L4))*1440,0))) -> 0 | O4: =IF(OR($K4="",$L4=""),0,ROUND(VLOOKUP($H4,DM_CA_LAM!$A$4:$F$6,6,FALSE())-$M4/60-$N4/60,2)) -> 8 | P4: Đi làm đủ công | Q4: 0 | T4: =$B4&"_"&TEXT($F4,"yyyymmdd") -> NV002_20260601 | U4: =VLOOKUP($P4,DM_TRANG_THAI!$A$4:$B$9,2,FALSE()) -> P
A5: 2 | B5: NV003 | C5: =VLOOKUP($B5,DM_NHAN_VIEN!$B$4:$F$18,2,FALSE()) -> Trần Thị Nhân Sự | D5: =VLOOKUP($B5,DM_NHAN_VIEN!$B$4:$F$18,3,FALSE()) -> Nhân sự | E5: =VLOOKUP($B5,DM_NHAN_VIEN!$B$4:$F$18,4,FALSE()) -> Trưởng phòng | F5: 46174 | G5: =CHOOSE(WEEKDAY(F5,2),"Thứ Hai","Thứ Ba","Thứ Tư","Thứ Năm","Thứ Sáu","Thứ Bảy","Chủ Nhật") -> Thứ Hai | H5: =VLOOKUP($B5,DM_NHAN_VIEN!$B$4:$F$18,5,FALSE()) -> Ca Hành Chính | I5: =VLOOKUP($H5,DM_CA_LAM!$A$4:$C$6,2,FALSE()) -> 07:30 | J5: =VLOOKUP($H5,DM_CA_LAM!$A$4:$C$6,3,FALSE()) -> 17:30 | K5: 07:20 | L5: 17:33 | M5: =IF($K5="","",MAX(0,ROUND((TIMEVALUE($K5)-TIMEVALUE($I5))*1440,0))) -> 0 | N5: =IF($L5="","",MAX(0,ROUND((TIMEVALUE($J5)-TIMEVALUE($L5))*1440,0))) -> 0 | O5: =IF(OR($K5="",$L5=""),0,ROUND(VLOOKUP($H5,DM_CA_LAM!$A$4:$F$6,6,FALSE())-$M5/60-$N5/60,2)) -> 8 | P5: Đi làm đủ công | Q5: 0 | T5: =$B5&"_"&TEXT($F5,"yyyymmdd") -> NV003_20260601 | U5: =VLOOKUP($P5,DM_TRANG_THAI!$A$4:$B$9,2,FALSE()) -> P
A6: 3 | B6: NV004 | C6: =VLOOKUP($B6,DM_NHAN_VIEN!$B$4:$F$18,2,FALSE()) -> Lê Văn Quản Đốc | D6: =VLOOKUP($B6,DM_NHAN_VIEN!$B$4:$F$18,3,FALSE()) -> Xưởng sản xuất | E6: =VLOOKUP($B6,DM_NHAN_VIEN!$B$4:$F$18,4,FALSE()) -> Quản đốc | F6: 46174 | G6: =CHOOSE(WEEKDAY(F6,2),"Thứ Hai","Thứ Ba","Thứ Tư","Thứ Năm","Thứ Sáu","Thứ Bảy","Chủ Nhật") -> Thứ Hai | H6: =VLOOKUP($B6,DM_NHAN_VIEN!$B$4:$F$18,5,FALSE()) -> Ca Hành Chính | I6: =VLOOKUP($H6,DM_CA_LAM!$A$4:$C$6,2,FALSE()) -> 07:30 | J6: =VLOOKUP($H6,DM_CA_LAM!$A$4:$C$6,3,FALSE()) -> 17:30 | K6: 07:26 | L6: 17:40 | M6: =IF($K6="","",MAX(0,ROUND((TIMEVALUE($K6)-TIMEVALUE($I6))*1440,0))) -> 0 | N6: =IF($L6="","",MAX(0,ROUND((TIMEVALUE($J6)-TIMEVALUE($L6))*1440,0))) -> 0 | O6: =IF(OR($K6="",$L6=""),0,ROUND(VLOOKUP($H6,DM_CA_LAM!$A$4:$F$6,6,FALSE())-$M6/60-$N6/60,2)) -> 8 | P6: Đi làm đủ công | Q6: 0 | T6: =$B6&"_"&TEXT($F6,"yyyymmdd") -> NV004_20260601 | U6: =VLOOKUP($P6,DM_TRANG_THAI!$A$4:$B$9,2,FALSE()) -> P
A7: 4 | B7: NV005 | C7: =VLOOKUP($B7,DM_NHAN_VIEN!$B$4:$F$18,2,FALSE()) -> Phạm Công Nhân | D7: =VLOOKUP($B7,DM_NHAN_VIEN!$B$4:$F$18,3,FALSE()) -> Xưởng sản xuất | E7: =VLOOKUP($B7,DM_NHAN_VIEN!$B$4:$F$18,4,FALSE()) -> Công nhân | F7: 46174 | G7: =CHOOSE(WEEKDAY(F7,2),"Thứ Hai","Thứ Ba","Thứ Tư","Thứ Năm","Thứ Sáu","Thứ Bảy","Chủ Nhật") -> Thứ Hai | H7: =VLOOKUP($B7,DM_NHAN_VIEN!$B$4:$F$18,5,FALSE()) -> Ca Hành Chính | I7: =VLOOKUP($H7,DM_CA_LAM!$A$4:$C$6,2,FALSE()) -> 07:30 | J7: =VLOOKUP($H7,DM_CA_LAM!$A$4:$C$6,3,FALSE()) -> 17:30 | K7: 07:29 | L7: 17:30 | M7: =IF($K7="","",MAX(0,ROUND((TIMEVALUE($K7)-TIMEVALUE($I7))*1440,0))) -> 0 | N7: =IF($L7="","",MAX(0,ROUND((TIMEVALUE($J7)-TIMEVALUE($L7))*1440,0))) -> 0 | O7: =IF(OR($K7="",$L7=""),0,ROUND(VLOOKUP($H7,DM_CA_LAM!$A$4:$F$6,6,FALSE())-$M7/60-$N7/60,2)) -> 8 | P7: Đi làm đủ công | Q7: 0 | T7: =$B7&"_"&TEXT($F7,"yyyymmdd") -> NV005_20260601 | U7: =VLOOKUP($P7,DM_TRANG_THAI!$A$4:$B$9,2,FALSE()) -> P
A8: 5 | B8: NV006 | C8: =VLOOKUP($B8,DM_NHAN_VIEN!$B$4:$F$18,2,FALSE()) -> Đỗ Thị Hà | D8: =VLOOKUP($B8,DM_NHAN_VIEN!$B$4:$F$18,3,FALSE()) -> Hành chính | E8: =VLOOKUP($B8,DM_NHAN_VIEN!$B$4:$F$18,4,FALSE()) -> Trưởng phòng | F8: 46174 | G8: =CHOOSE(WEEKDAY(F8,2),"Thứ Hai","Thứ Ba","Thứ Tư","Thứ Năm","Thứ Sáu","Thứ Bảy","Chủ Nhật") -> Thứ Hai | H8: =VLOOKUP($B8,DM_NHAN_VIEN!$B$4:$F$18,5,FALSE()) -> Ca Hành Chính | I8: =VLOOKUP($H8,DM_CA_LAM!$A$4:$C$6,2,FALSE()) -> 07:30 | J8: =VLOOKUP($H8,DM_CA_LAM!$A$4:$C$6,3,FALSE()) -> 17:30 | K8: 07:28 | L8: 17:36 | M8: =IF($K8="","",MAX(0,ROUND((TIMEVALUE($K8)-TIMEVALUE($I8))*1440,0))) -> 0 | N8: =IF($L8="","",MAX(0,ROUND((TIMEVALUE($J8)-TIMEVALUE($L8))*1440,0))) -> 0 | O8: =IF(OR($K8="",$L8=""),0,ROUND(VLOOKUP($H8,DM_CA_LAM!$A$4:$F$6,6,FALSE())-$M8/60-$N8/60,2)) -> 8 | P8: Đi làm đủ công | Q8: 0 | T8: =$B8&"_"&TEXT($F8,"yyyymmdd") -> NV006_20260601 | U8: =VLOOKUP($P8,DM_TRANG_THAI!$A$4:$B$9,2,FALSE()) -> P
A9: 6 | B9: NV007 | C9: =VLOOKUP($B9,DM_NHAN_VIEN!$B$4:$F$18,2,FALSE()) -> Ngô Văn Tài | D9: =VLOOKUP($B9,DM_NHAN_VIEN!$B$4:$F$18,3,FALSE()) -> Hành chính | E9: =VLOOKUP($B9,DM_NHAN_VIEN!$B$4:$F$18,4,FALSE()) -> Phó phòng | F9: 46174 | G9: =CHOOSE(WEEKDAY(F9,2),"Thứ Hai","Thứ Ba","Thứ Tư","Thứ Năm","Thứ Sáu","Thứ Bảy","Chủ Nhật") -> Thứ Hai | H9: =VLOOKUP($B9,DM_NHAN_VIEN!$B$4:$F$18,5,FALSE()) -> Ca Hành Chính | I9: =VLOOKUP($H9,DM_CA_LAM!$A$4:$C$6,2,FALSE()) -> 07:30 | J9: =VLOOKUP($H9,DM_CA_LAM!$A$4:$C$6,3,FALSE()) -> 17:30 | K9: 07:22 | L9: 17:36 | M9: =IF($K9="","",MAX(0,ROUND((TIMEVALUE($K9)-TIMEVALUE($I9))*1440,0))) -> 0 | N9: =IF($L9="","",MAX(0,ROUND((TIMEVALUE($J9)-TIMEVALUE($L9))*1440,0))) -> 0 | O9: =IF(OR($K9="",$L9=""),0,ROUND(VLOOKUP($H9,DM_CA_LAM!$A$4:$F$6,6,FALSE())-$M9/60-$N9/60,2)) -> 8 | P9: Đi làm đủ công | Q9: 2.5 | R9: Hỗ trợ kiểm kê cuối tháng | T9: =$B9&"_"&TEXT($F9,"yyyymmdd") -> NV007_20260601 | U9: =VLOOKUP($P9,DM_TRANG_THAI!$A$4:$B$9,2,FALSE()) -> P
A10: 7 | B10: NV008 | C10: =VLOOKUP($B10,DM_NHAN_VIEN!$B$4:$F$18,2,FALSE()) -> Vũ Thị Nga | D10: =VLOOKUP($B10,DM_NHAN_VIEN!$B$4:$F$18,3,FALSE()) -> Hành chính | E10: =VLOOKUP($B10,DM_NHAN_VIEN!$B$4:$F$18,4,FALSE()) -> Chuyên viên | F10: 46174 | G10: =CHOOSE(WEEKDAY(F10,2),"Thứ Hai","Thứ Ba","Thứ Tư","Thứ Năm","Thứ Sáu","Thứ Bảy","Chủ Nhật") -> Thứ Hai | H10: =VLOOKUP($B10,DM_NHAN_VIEN!$B$4:$F$18,5,FALSE()) -> Ca Hành Chính | I10: =VLOOKUP($H10,DM_CA_LAM!$A$4:$C$6,2,FALSE()) -> 07:30 | J10: =VLOOKUP($H10,DM_CA_LAM!$A$4:$C$6,3,FALSE()) -> 17:30 | M10: =IF($K10="","",MAX(0,ROUND((TIMEVALUE($K10)-TIMEVALUE($I10))*1440,0))) | N10: =IF($L10="","",MAX(0,ROUND((TIMEVALUE($J10)-TIMEVALUE($L10))*1440,0))) | O10: =IF(OR($K10="",$L10=""),0,ROUND(VLOOKUP($H10,DM_CA_LAM!$A$4:$F$6,6,FALSE())-$M10/60-$N10/60,2)) -> 0 | P10: Nghỉ phép năm | Q10: 0 | T10: =$B10&"_"&TEXT($F10,"yyyymmdd") -> NV008_20260601 | U10: =VLOOKUP($P10,DM_TRANG_THAI!$A$4:$B$9,2,FALSE()) -> NP
A11: 8 | B11: NV010 | C11: =VLOOKUP($B11,DM_NHAN_VIEN!$B$4:$F$18,2,FALSE()) -> Đặng Thị Hồng | D11: =VLOOKUP($B11,DM_NHAN_VIEN!$B$4:$F$18,3,FALSE()) -> Nhân sự | E11: =VLOOKUP($B11,DM_NHAN_VIEN!$B$4:$F$18,4,FALSE()) -> Chuyên viên | F11: 46174 | G11: =CHOOSE(WEEKDAY(F11,2),"Thứ Hai","Thứ Ba","Thứ Tư","Thứ Năm","Thứ Sáu","Thứ Bảy","Chủ Nhật") -> Thứ Hai | H11: =VLOOKUP($B11,DM_NHAN_VIEN!$B$4:$F$18,5,FALSE()) -> Ca Hành Chính | I11: =VLOOKUP($H11,DM_CA_LAM!$A$4:$C$6,2,FALSE()) -> 07:30 | J11: =VLOOKUP($H11,DM_CA_LAM!$A$4:$C$6,3,FALSE()) -> 17:30 | K11: 08:05 | L11: 17:34 | M11: =IF($K11="","",MAX(0,ROUND((TIMEVALUE($K11)-TIMEVALUE($I11))*1440,0))) -> 35 | N11: =IF($L11="","",MAX(0,ROUND((TIMEVALUE($J11)-TIMEVALUE($L11))*1440,0))) -> 0 | O11: =IF(OR($K11="",$L11=""),0,ROUND(VLOOKUP($H11,DM_CA_LAM!$A$4:$F$6,6,FALSE())-$M11/60-$N11/60,2)) -> 7.42 | P11: Đi muộn | Q11: 0 | S11: Kẹt xe | T11: =$B11&"_"&TEXT($F11,"yyyymmdd") -> NV010_20260601 | U11: =VLOOKUP($P11,DM_TRANG_THAI!$A$4:$B$9,2,FALSE()) -> L
A12: 9 | B12: NV011 | C12: =VLOOKUP($B12,DM_NHAN_VIEN!$B$4:$F$18,2,FALSE()) -> Chu Văn Minh | D12: =VLOOKUP($B12,DM_NHAN_VIEN!$B$4:$F$18,3,FALSE()) -> Nhân sự | E12: =VLOOKUP($B12,DM_NHAN_VIEN!$B$4:$F$18,4,FALSE()) -> Chuyên viên | F12: 46174 | G12: =CHOOSE(WEEKDAY(F12,2),"Thứ Hai","Thứ Ba","Thứ Tư","Thứ Năm","Thứ Sáu","Thứ Bảy","Chủ Nhật") -> Thứ Hai | H12: =VLOOKUP($B12,DM_NHAN_VIEN!$B$4:$F$18,5,FALSE()) -> Ca Hành Chính | I12: =VLOOKUP($H12,DM_CA_LAM!$A$4:$C$6,2,FALSE()) -> 07:30 | J12: =VLOOKUP($H12,DM_CA_LAM!$A$4:$C$6,3,FALSE()) -> 17:30 | K12: 07:28 | L12: 17:30 | M12: =IF($K12="","",MAX(0,ROUND((TIMEVALUE($K12)-TIMEVALUE($I12))*1440,0))) -> 0 | N12: =IF($L12="","",MAX(0,ROUND((TIMEVALUE($J12)-TIMEVALUE($L12))*1440,0))) -> 0 | O12: =IF(OR($K12="",$L12=""),0,ROUND(VLOOKUP($H12,DM_CA_LAM!$A$4:$F$6,6,FALSE())-$M12/60-$N12/60,2)) -> 8 | P12: Đi làm đủ công | Q12: 0 | T12: =$B12&"_"&TEXT($F12,"yyyymmdd") -> NV011_20260601 | U12: =VLOOKUP($P12,DM_TRANG_THAI!$A$4:$B$9,2,FALSE()) -> P
A13: 10 | B13: NV014 | C13: =VLOOKUP($B13,DM_NHAN_VIEN!$B$4:$F$18,2,FALSE()) -> Phan Thị Khánh | D13: =VLOOKUP($B13,DM_NHAN_VIEN!$B$4:$F$18,3,FALSE()) -> Kế toán | E13: =VLOOKUP($B13,DM_NHAN_VIEN!$B$4:$F$18,4,FALSE()) -> Trưởng phòng | F13: 46174 | G13: =CHOOSE(WEEKDAY(F13,2),"Thứ Hai","Thứ Ba","Thứ Tư","Thứ Năm","Thứ Sáu","Thứ Bảy","Chủ Nhật") -> Thứ Hai | H13: =VLOOKUP($B13,DM_NHAN_VIEN!$B$4:$F$18,5,FALSE()) -> Ca Hành Chính | I13: =VLOOKUP($H13,DM_CA_LAM!$A$4:$C$6,2,FALSE()) -> 07:30 | J13: =VLOOKUP($H13,DM_CA_LAM!$A$4:$C$6,3,FALSE()) -> 17:30 | K13: 08:02 | L13: 17:40 | M13: =IF($K13="","",MAX(0,ROUND((TIMEVALUE($K13)-TIMEVALUE($I13))*1440,0))) -> 32 | N13: =IF($L13="","",MAX(0,ROUND((TIMEVALUE($J13)-TIMEVALUE($L13))*1440,0))) -> 0 | O13: =IF(OR($K13="",$L13=""),0,ROUND(VLOOKUP($H13,DM_CA_LAM!$A$4:$F$6,6,FALSE())-$M13/60-$N13/60,2)) -> 7.47 | P13: Đi muộn | Q13: 0 | T13: =$B13&"_"&TEXT($F13,"yyyymmdd") -> NV014_20260601 | U13: =VLOOKUP($P13,DM_TRANG_THAI!$A$4:$B$9,2,FALSE()) -> L
A14: 11 | B14: NV015 | C14: =VLOOKUP($B14,DM_NHAN_VIEN!$B$4:$F$18,2,FALSE()) -> Trịnh Văn Hùng | D14: =VLOOKUP($B14,DM_NHAN_VIEN!$B$4:$F$18,3,FALSE()) -> Kế toán | E14: =VLOOKUP($B14,DM_NHAN_VIEN!$B$4:$F$18,4,FALSE()) -> Phó phòng | F14: 46174 | G14: =CHOOSE(WEEKDAY(F14,2),"Thứ Hai","Thứ Ba","Thứ Tư","Thứ Năm","Thứ Sáu","Thứ Bảy","Chủ Nhật") -> Thứ Hai | H14: =VLOOKUP($B14,DM_NHAN_VIEN!$B$4:$F$18,5,FALSE()) -> Ca Hành Chính | I14: =VLOOKUP($H14,DM_CA_LAM!$A$4:$C$6,2,FALSE()) -> 07:30 | J14: =VLOOKUP($H14,DM_CA_LAM!$A$4:$C$6,3,FALSE()) -> 17:30 | K14: 07:23 | L14: 17:42 | M14: =IF($K14="","",MAX(0,ROUND((TIMEVALUE($K14)-TIMEVALUE($I14))*1440,0))) -> 0 | N14: =IF($L14="","",MAX(0,ROUND((TIMEVALUE($J14)-TIMEVALUE($L14))*1440,0))) -> 0 | O14: =IF(OR($K14="",$L14=""),0,ROUND(VLOOKUP($H14,DM_CA_LAM!$A$4:$F$6,6,FALSE())-$M14/60-$N14/60,2)) -> 8 | P14: Đi làm đủ công | Q14: 0 | T14: =$B14&"_"&TEXT($F14,"yyyymmdd") -> NV015_20260601 | U14: =VLOOKUP($P14,DM_TRANG_THAI!$A$4:$B$9,2,FALSE()) -> P
A15: 12 | B15: NV019 | C15: =VLOOKUP($B15,DM_NHAN_VIEN!$B$4:$F$18,2,FALSE()) -> Hoàng Văn Lộc | D15: =VLOOKUP($B15,DM_NHAN_VIEN!$B$4:$F$18,3,FALSE()) -> Kinh doanh | E15: =VLOOKUP($B15,DM_NHAN_VIEN!$B$4:$F$18,4,FALSE()) -> Trưởng phòng | F15: 46174 | G15: =CHOOSE(WEEKDAY(F15,2),"Thứ Hai","Thứ Ba","Thứ Tư","Thứ Năm","Thứ Sáu","Thứ Bảy","Chủ Nhật") -> Thứ Hai | H15: =VLOOKUP($B15,DM_NHAN_VIEN!$B$4:$F$18,5,FALSE()) -> Ca Hành Chính | I15: =VLOOKUP($H15,DM_CA_LAM!$A$4:$C$6,2,FALSE()) -> 07:30 | J15: =VLOOKUP($H15,DM_CA_LAM!$A$4:$C$6,3,FALSE()) -> 17:30 | K15: 07:25 | L15: 17:30 | M15: =IF($K15="","",MAX(0,ROUND((TIMEVALUE($K15)-TIMEVALUE($I15))*1440,0))) -> 0 | N15: =IF($L15="","",MAX(0,ROUND((TIMEVALUE($J15)-TIMEVALUE($L15))*1440,0))) -> 0 | O15: =IF(OR($K15="",$L15=""),0,ROUND(VLOOKUP($H15,DM_CA_LAM!$A$4:$F$6,6,FALSE())-$M15/60-$N15/60,2)) -> 8 | P15: Đi làm đủ công | Q15: 0 | T15: =$B15&"_"&TEXT($F15,"yyyymmdd") -> NV019_20260601 | U15: =VLOOKUP($P15,DM_TRANG_THAI!$A$4:$B$9,2,FALSE()) -> P
A16: 13 | B16: NV021 | C16: =VLOOKUP($B16,DM_NHAN_VIEN!$B$4:$F$18,2,FALSE()) -> Nguyễn Văn Phú | D16: =VLOOKUP($B16,DM_NHAN_VIEN!$B$4:$F$18,3,FALSE()) -> Kinh doanh | E16: =VLOOKUP($B16,DM_NHAN_VIEN!$B$4:$F$18,4,FALSE()) -> Nhân viên | F16: 46174 | G16: =CHOOSE(WEEKDAY(F16,2),"Thứ Hai","Thứ Ba","Thứ Tư","Thứ Năm","Thứ Sáu","Thứ Bảy","Chủ Nhật") -> Thứ Hai | H16: =VLOOKUP($B16,DM_NHAN_VIEN!$B$4:$F$18,5,FALSE()) -> Ca Hành Chính | I16: =VLOOKUP($H16,DM_CA_LAM!$A$4:$C$6,2,FALSE()) -> 07:30 | J16: =VLOOKUP($H16,DM_CA_LAM!$A$4:$C$6,3,FALSE()) -> 17:30 | K16: 07:25 | L16: 17:39 | M16: =IF($K16="","",MAX(0,ROUND((TIMEVALUE($K16)-TIMEVALUE($I16))*1440,0))) -> 0 | N16: =IF($L16="","",MAX(0,ROUND((TIMEVALUE($J16)-TIMEVALUE($L16))*1440,0))) -> 0 | O16: =IF(OR($K16="",$L16=""),0,ROUND(VLOOKUP($H16,DM_CA_LAM!$A$4:$F$6,6,FALSE())-$M16/60-$N16/60,2)) -> 8 | P16: Đi làm đủ công | Q16: 0 | T16: =$B16&"_"&TEXT($F16,"yyyymmdd") -> NV021_20260601 | U16: =VLOOKUP($P16,DM_TRANG_THAI!$A$4:$B$9,2,FALSE()) -> P
A17: 14 | B17: NV029 | C17: =VLOOKUP($B17,DM_NHAN_VIEN!$B$4:$F$18,2,FALSE()) -> Lý Văn Dũng | D17: =VLOOKUP($B17,DM_NHAN_VIEN!$B$4:$F$18,3,FALSE()) -> Xưởng sản xuất | E17: =VLOOKUP($B17,DM_NHAN_VIEN!$B$4:$F$18,4,FALSE()) -> Tổ trưởng | F17: 46174 | G17: =CHOOSE(WEEKDAY(F17,2),"Thứ Hai","Thứ Ba","Thứ Tư","Thứ Năm","Thứ Sáu","Thứ Bảy","Chủ Nhật") -> Thứ Hai | H17: =VLOOKUP($B17,DM_NHAN_VIEN!$B$4:$F$18,5,FALSE()) -> Ca Hành Chính | I17: =VLOOKUP($H17,DM_CA_LAM!$A$4:$C$6,2,FALSE()) -> 07:30 | J17: =VLOOKUP($H17,DM_CA_LAM!$A$4:$C$6,3,FALSE()) -> 17:30 | K17: 07:21 | L17: 17:42 | M17: =IF($K17="","",MAX(0,ROUND((TIMEVALUE($K17)-TIMEVALUE($I17))*1440,0))) -> 0 | N17: =IF($L17="","",MAX(0,ROUND((TIMEVALUE($J17)-TIMEVALUE($L17))*1440,0))) -> 0 | O17: =IF(OR($K17="",$L17=""),0,ROUND(VLOOKUP($H17,DM_CA_LAM!$A$4:$F$6,6,FALSE())-$M17/60-$N17/60,2)) -> 8 | P17: Đi làm đủ công | Q17: 0 | T17: =$B17&"_"&TEXT($F17,"yyyymmdd") -> NV029_20260601 | U17: =VLOOKUP($P17,DM_TRANG_THAI!$A$4:$B$9,2,FALSE()) -> P
A18: 15 | B18: NV030 | C18: =VLOOKUP($B18,DM_NHAN_VIEN!$B$4:$F$18,2,FALSE()) -> Tống Văn Thắng | D18: =VLOOKUP($B18,DM_NHAN_VIEN!$B$4:$F$18,3,FALSE()) -> Xưởng sản xuất | E18: =VLOOKUP($B18,DM_NHAN_VIEN!$B$4:$F$18,4,FALSE()) -> Tổ trưởng | F18: 46174 | G18: =CHOOSE(WEEKDAY(F18,2),"Thứ Hai","Thứ Ba","Thứ Tư","Thứ Năm","Thứ Sáu","Thứ Bảy","Chủ Nhật") -> Thứ Hai | H18: =VLOOKUP($B18,DM_NHAN_VIEN!$B$4:$F$18,5,FALSE()) -> Ca Hành Chính | I18: =VLOOKUP($H18,DM_CA_LAM!$A$4:$C$6,2,FALSE()) -> 07:30 | J18: =VLOOKUP($H18,DM_CA_LAM!$A$4:$C$6,3,FALSE()) -> 17:30 | K18: 07:24 | L18: 17:42 | M18: =IF($K18="","",MAX(0,ROUND((TIMEVALUE($K18)-TIMEVALUE($I18))*1440,0))) -> 0 | N18: =IF($L18="","",MAX(0,ROUND((TIMEVALUE($J18)-TIMEVALUE($L18))*1440,0))) -> 0 | O18: =IF(OR($K18="",$L18=""),0,ROUND(VLOOKUP($H18,DM_CA_LAM!$A$4:$F$6,6,FALSE())-$M18/60-$N18/60,2)) -> 8 | P18: Đi làm đủ công | Q18: 0 | T18: =$B18&"_"&TEXT($F18,"yyyymmdd") -> NV030_20260601 | U18: =VLOOKUP($P18,DM_TRANG_THAI!$A$4:$B$9,2,FALSE()) -> P
A19: 16 | B19: NV002 | C19: =VLOOKUP($B19,DM_NHAN_VIEN!$B$4:$F$18,2,FALSE()) -> Nguyễn Văn Giám Đốc | D19: =VLOOKUP($B19,DM_NHAN_VIEN!$B$4:$F$18,3,FALSE()) -> Hành chính | E19: =VLOOKUP($B19,DM_NHAN_VIEN!$B$4:$F$18,4,FALSE()) -> Giám đốc | F19: 46175 | G19: =CHOOSE(WEEKDAY(F19,2),"Thứ Hai","Thứ Ba","Thứ Tư","Thứ Năm","Thứ Sáu","Thứ Bảy","Chủ Nhật") -> Thứ Ba | H19: =VLOOKUP($B19,DM_NHAN_VIEN!$B$4:$F$18,5,FALSE()) -> Ca Hành Chính | I19: =VLOOKUP($H19,DM_CA_LAM!$A$4:$C$6,2,FALSE()) -> 07:30 | J19: =VLOOKUP($H19,DM_CA_LAM!$A$4:$C$6,3,FALSE()) -> 17:30 | K19: 07:21 | L19: 17:32 | M19: =IF($K19="","",MAX(0,ROUND((TIMEVALUE($K19)-TIMEVALUE($I19))*1440,0))) -> 0 | N19: =IF($L19="","",MAX(0,ROUND((TIMEVALUE($J19)-TIMEVALUE($L19))*1440,0))) -> 0 | O19: =IF(OR($K19="",$L19=""),0,ROUND(VLOOKUP($H19,DM_CA_LAM!$A$4:$F$6,6,FALSE())-$M19/60-$N19/60,2)) -> 8 | P19: Đi làm đủ công | Q19: 0 | T19: =$B19&"_"&TEXT($F19,"yyyymmdd") -> NV002_20260602 | U19: =VLOOKUP($P19,DM_TRANG_THAI!$A$4:$B$9,2,FALSE()) -> P
A20: 17 | B20: NV003 | C20: =VLOOKUP($B20,DM_NHAN_VIEN!$B$4:$F$18,2,FALSE()) -> Trần Thị Nhân Sự | D20: =VLOOKUP($B20,DM_NHAN_VIEN!$B$4:$F$18,3,FALSE()) -> Nhân sự | E20: =VLOOKUP($B20,DM_NHAN_VIEN!$B$4:$F$18,4,FALSE()) -> Trưởng phòng | F20: 46175 | G20: =CHOOSE(WEEKDAY(F20,2),"Thứ Hai","Thứ Ba","Thứ Tư","Thứ Năm","Thứ Sáu","Thứ Bảy","Chủ Nhật") -> Thứ Ba | H20: =VLOOKUP($B20,DM_NHAN_VIEN!$B$4:$F$18,5,FALSE()) -> Ca Hành Chính | I20: =VLOOKUP($H20,DM_CA_LAM!$A$4:$C$6,2,FALSE()) -> 07:30 | J20: =VLOOKUP($H20,DM_CA_LAM!$A$4:$C$6,3,FALSE()) -> 17:30 | K20: 07:30 | L20: 17:43 | M20: =IF($K20="","",MAX(0,ROUND((TIMEVALUE($K20)-TIMEVALUE($I20))*1440,0))) -> 0 | N20: =IF($L20="","",MAX(0,ROUND((TIMEVALUE($J20)-TIMEVALUE($L20))*1440,0))) -> 0 | O20: =IF(OR($K20="",$L20=""),0,ROUND(VLOOKUP($H20,DM_CA_LAM!$A$4:$F$6,6,FALSE())-$M20/60-$N20/60,2)) -> 8 | P20: Đi làm đủ công | Q20: 0 | T20: =$B20&"_"&TEXT($F20,"yyyymmdd") -> NV003_20260602 | U20: =VLOOKUP($P20,DM_TRANG_THAI!$A$4:$B$9,2,FALSE()) -> P
A21: 18 | B21: NV004 | C21: =VLOOKUP($B21,DM_NHAN_VIEN!$B$4:$F$18,2,FALSE()) -> Lê Văn Quản Đốc | D21: =VLOOKUP($B21,DM_NHAN_VIEN!$B$4:$F$18,3,FALSE()) -> Xưởng sản xuất | E21: =VLOOKUP($B21,DM_NHAN_VIEN!$B$4:$F$18,4,FALSE()) -> Quản đốc | F21: 46175 | G21: =CHOOSE(WEEKDAY(F21,2),"Thứ Hai","Thứ Ba","Thứ Tư","Thứ Năm","Thứ Sáu","Thứ Bảy","Chủ Nhật") -> Thứ Ba | H21: =VLOOKUP($B21,DM_NHAN_VIEN!$B$4:$F$18,5,FALSE()) -> Ca Hành Chính | I21: =VLOOKUP($H21,DM_CA_LAM!$A$4:$C$6,2,FALSE()) -> 07:30 | J21: =VLOOKUP($H21,DM_CA_LAM!$A$4:$C$6,3,FALSE()) -> 17:30 | K21: 07:23 | L21: 17:36 | M21: =IF($K21="","",MAX(0,ROUND((TIMEVALUE($K21)-TIMEVALUE($I21))*1440,0))) -> 0 | N21: =IF($L21="","",MAX(0,ROUND((TIMEVALUE($J21)-TIMEVALUE($L21))*1440,0))) -> 0 | O21: =IF(OR($K21="",$L21=""),0,ROUND(VLOOKUP($H21,DM_CA_LAM!$A$4:$F$6,6,FALSE())-$M21/60-$N21/60,2)) -> 8 | P21: Đi làm đủ công | Q21: 0 | T21: =$B21&"_"&TEXT($F21,"yyyymmdd") -> NV004_20260602 | U21: =VLOOKUP($P21,DM_TRANG_THAI!$A$4:$B$9,2,FALSE()) -> P
A22: 19 | B22: NV005 | C22: =VLOOKUP($B22,DM_NHAN_VIEN!$B$4:$F$18,2,FALSE()) -> Phạm Công Nhân | D22: =VLOOKUP($B22,DM_NHAN_VIEN!$B$4:$F$18,3,FALSE()) -> Xưởng sản xuất | E22: =VLOOKUP($B22,DM_NHAN_VIEN!$B$4:$F$18,4,FALSE()) -> Công nhân | F22: 46175 | G22: =CHOOSE(WEEKDAY(F22,2),"Thứ Hai","Thứ Ba","Thứ Tư","Thứ Năm","Thứ Sáu","Thứ Bảy","Chủ Nhật") -> Thứ Ba | H22: =VLOOKUP($B22,DM_NHAN_VIEN!$B$4:$F$18,5,FALSE()) -> Ca Hành Chính | I22: =VLOOKUP($H22,DM_CA_LAM!$A$4:$C$6,2,FALSE()) -> 07:30 | J22: =VLOOKUP($H22,DM_CA_LAM!$A$4:$C$6,3,FALSE()) -> 17:30 | K22: 07:30 | L22: 17:33 | M22: =IF($K22="","",MAX(0,ROUND((TIMEVALUE($K22)-TIMEVALUE($I22))*1440,0))) -> 0 | N22: =IF($L22="","",MAX(0,ROUND((TIMEVALUE($J22)-TIMEVALUE($L22))*1440,0))) -> 0 | O22: =IF(OR($K22="",$L22=""),0,ROUND(VLOOKUP($H22,DM_CA_LAM!$A$4:$F$6,6,FALSE())-$M22/60-$N22/60,2)) -> 8 | P22: Đi làm đủ công | Q22: 0 | T22: =$B22&"_"&TEXT($F22,"yyyymmdd") -> NV005_20260602 | U22: =VLOOKUP($P22,DM_TRANG_THAI!$A$4:$B$9,2,FALSE()) -> P
A23: 20 | B23: NV006 | C23: =VLOOKUP($B23,DM_NHAN_VIEN!$B$4:$F$18,2,FALSE()) -> Đỗ Thị Hà | D23: =VLOOKUP($B23,DM_NHAN_VIEN!$B$4:$F$18,3,FALSE()) -> Hành chính | E23: =VLOOKUP($B23,DM_NHAN_VIEN!$B$4:$F$18,4,FALSE()) -> Trưởng phòng | F23: 46175 | G23: =CHOOSE(WEEKDAY(F23,2),"Thứ Hai","Thứ Ba","Thứ Tư","Thứ Năm","Thứ Sáu","Thứ Bảy","Chủ Nhật") -> Thứ Ba | H23: =VLOOKUP($B23,DM_NHAN_VIEN!$B$4:$F$18,5,FALSE()) -> Ca Hành Chính | I23: =VLOOKUP($H23,DM_CA_LAM!$A$4:$C$6,2,FALSE()) -> 07:30 | J23: =VLOOKUP($H23,DM_CA_LAM!$A$4:$C$6,3,FALSE()) -> 17:30 | K23: 07:30 | L23: 17:40 | M23: =IF($K23="","",MAX(0,ROUND((TIMEVALUE($K23)-TIMEVALUE($I23))*1440,0))) -> 0 | N23: =IF($L23="","",MAX(0,ROUND((TIMEVALUE($J23)-TIMEVALUE($L23))*1440,0))) -> 0 | O23: =IF(OR($K23="",$L23=""),0,ROUND(VLOOKUP($H23,DM_CA_LAM!$A$4:$F$6,6,FALSE())-$M23/60-$N23/60,2)) -> 8 | P23: Đi làm đủ công | Q23: 0 | T23: =$B23&"_"&TEXT($F23,"yyyymmdd") -> NV006_20260602 | U23: =VLOOKUP($P23,DM_TRANG_THAI!$A$4:$B$9,2,FALSE()) -> P
... A28: 25 | B28: NV014 | C28: =VLOOKUP($B28,DM_NHAN_VIEN!$B$4:$F$18,2,FALSE()) -> Phan Thị Khánh | D28: =VLOOKUP($B28,DM_NHAN_VIEN!$B$4:$F$18,3,FALSE()) -> Kế toán | E28: =VLOOKUP($B28,DM_NHAN_VIEN!$B$4:$F$18,4,FALSE()) -> Trưởng phòng | F28: 46175 | G28: =CHOOSE(WEEKDAY(F28,2),"Thứ Hai","Thứ Ba","Thứ Tư","Thứ Năm","Thứ Sáu","Thứ Bảy","Chủ Nhật") -> Thứ Ba | H28: =VLOOKUP($B28,DM_NHAN_VIEN!$B$4:$F$18,5,FALSE()) -> Ca Hành Chính | I28: =VLOOKUP($H28,DM_CA_LAM!$A$4:$C$6,2,FALSE()) -> 07:30 | J28: =VLOOKUP($H28,DM_CA_LAM!$A$4:$C$6,3,FALSE()) -> 17:30 | K28: 07:27 | L28: 17:31 | M28: =IF($K28="","",MAX(0,ROUND((TIMEVALUE($K28)-TIMEVALUE($I28))*1440,0))) -> 0 | N28: =IF($L28="","",MAX(0,ROUND((TIMEVALUE($J28)-TIMEVALUE($L28))*1440,0))) -> 0 | O28: =IF(OR($K28="",$L28=""),0,ROUND(VLOOKUP($H28,DM_CA_LAM!$A$4:$F$6,6,FALSE())-$M28/60-$N28/60,2)) -> 8 | P28: Đi làm đủ công | Q28: 0 | T28: =$B28&"_"&TEXT($F28,"yyyymmdd") -> NV014_20260602 | U28: =VLOOKUP($P28,DM_TRANG_THAI!$A$4:$B$9,2,FALSE()) -> P
A29: 26 | B29: NV015 | C29: =VLOOKUP($B29,DM_NHAN_VIEN!$B$4:$F$18,2,FALSE()) -> Trịnh Văn Hùng | D29: =VLOOKUP($B29,DM_NHAN_VIEN!$B$4:$F$18,3,FALSE()) -> Kế toán | E29: =VLOOKUP($B29,DM_NHAN_VIEN!$B$4:$F$18,4,FALSE()) -> Phó phòng | F29: 46175 | G29: =CHOOSE(WEEKDAY(F29,2),"Thứ Hai","Thứ Ba","Thứ Tư","Thứ Năm","Thứ Sáu","Thứ Bảy","Chủ Nhật") -> Thứ Ba | H29: =VLOOKUP($B29,DM_NHAN_VIEN!$B$4:$F$18,5,FALSE()) -> Ca Hành Chính | I29: =VLOOKUP($H29,DM_CA_LAM!$A$4:$C$6,2,FALSE()) -> 07:30 | J29: =VLOOKUP($H29,DM_CA_LAM!$A$4:$C$6,3,FALSE()) -> 17:30 | K29: 07:46 | L29: 17:31 | M29: =IF($K29="","",MAX(0,ROUND((TIMEVALUE($K29)-TIMEVALUE($I29))*1440,0))) -> 16 | N29: =IF($L29="","",MAX(0,ROUND((TIMEVALUE($J29)-TIMEVALUE($L29))*1440,0))) -> 0 | O29: =IF(OR($K29="",$L29=""),0,ROUND(VLOOKUP($H29,DM_CA_LAM!$A$4:$F$6,6,FALSE())-$M29/60-$N29/60,2)) -> 7.73 | P29: Đi muộn | Q29: 3 | R29: Xử lý đơn hàng gấp | T29: =$B29&"_"&TEXT($F29,"yyyymmdd") -> NV015_20260602 | U29: =VLOOKUP($P29,DM_TRANG_THAI!$A$4:$B$9,2,FALSE()) -> L
A30: 27 | B30: NV019 | C30: =VLOOKUP($B30,DM_NHAN_VIEN!$B$4:$F$18,2,FALSE()) -> Hoàng Văn Lộc | D30: =VLOOKUP($B30,DM_NHAN_VIEN!$B$4:$F$18,3,FALSE()) -> Kinh doanh | E30: =VLOOKUP($B30,DM_NHAN_VIEN!$B$4:$F$18,4,FALSE()) -> Trưởng phòng | F30: 46175 | G30: =CHOOSE(WEEKDAY(F30,2),"Thứ Hai","Thứ Ba","Thứ Tư","Thứ Năm","Thứ Sáu","Thứ Bảy","Chủ Nhật") -> Thứ Ba | H30: =VLOOKUP($B30,DM_NHAN_VIEN!$B$4:$F$18,5,FALSE()) -> Ca Hành Chính | I30: =VLOOKUP($H30,DM_CA_LAM!$A$4:$C$6,2,FALSE()) -> 07:30 | J30: =VLOOKUP($H30,DM_CA_LAM!$A$4:$C$6,3,FALSE()) -> 17:30 | K30: 07:26 | L30: 17:33 | M30: =IF($K30="","",MAX(0,ROUND((TIMEVALUE($K30)-TIMEVALUE($I30))*1440,0))) -> 0 | N30: =IF($L30="","",MAX(0,ROUND((TIMEVALUE($J30)-TIMEVALUE($L30))*1440,0))) -> 0 | O30: =IF(OR($K30="",$L30=""),0,ROUND(VLOOKUP($H30,DM_CA_LAM!$A$4:$F$6,6,FALSE())-$M30/60-$N30/60,2)) -> 8 | P30: Đi làm đủ công | Q30: 0 | T30: =$B30&"_"&TEXT($F30,"yyyymmdd") -> NV019_20260602 | U30: =VLOOKUP($P30,DM_TRANG_THAI!$A$4:$B$9,2,FALSE()) -> P
A31: 28 | B31: NV021 | C31: =VLOOKUP($B31,DM_NHAN_VIEN!$B$4:$F$18,2,FALSE()) -> Nguyễn Văn Phú | D31: =VLOOKUP($B31,DM_NHAN_VIEN!$B$4:$F$18,3,FALSE()) -> Kinh doanh | E31: =VLOOKUP($B31,DM_NHAN_VIEN!$B$4:$F$18,4,FALSE()) -> Nhân viên | F31: 46175 | G31: =CHOOSE(WEEKDAY(F31,2),"Thứ Hai","Thứ Ba","Thứ Tư","Thứ Năm","Thứ Sáu","Thứ Bảy","Chủ Nhật") -> Thứ Ba | H31: =VLOOKUP($B31,DM_NHAN_VIEN!$B$4:$F$18,5,FALSE()) -> Ca Hành Chính | I31: =VLOOKUP($H31,DM_CA_LAM!$A$4:$C$6,2,FALSE()) -> 07:30 | J31: =VLOOKUP($H31,DM_CA_LAM!$A$4:$C$6,3,FALSE()) -> 17:30 | K31: 07:29 | L31: 17:32 | M31: =IF($K31="","",MAX(0,ROUND((TIMEVALUE($K31)-TIMEVALUE($I31))*1440,0))) -> 0 | N31: =IF($L31="","",MAX(0,ROUND((TIMEVALUE($J31)-TIMEVALUE($L31))*1440,0))) -> 0 | O31: =IF(OR($K31="",$L31=""),0,ROUND(VLOOKUP($H31,DM_CA_LAM!$A$4:$F$6,6,FALSE())-$M31/60-$N31/60,2)) -> 8 | P31: Đi làm đủ công | Q31: 0 | T31: =$B31&"_"&TEXT($F31,"yyyymmdd") -> NV021_20260602 | U31: =VLOOKUP($P31,DM_TRANG_THAI!$A$4:$B$9,2,FALSE()) -> P
A32: 29 | B32: NV029 | C32: =VLOOKUP($B32,DM_NHAN_VIEN!$B$4:$F$18,2,FALSE()) -> Lý Văn Dũng | D32: =VLOOKUP($B32,DM_NHAN_VIEN!$B$4:$F$18,3,FALSE()) -> Xưởng sản xuất | E32: =VLOOKUP($B32,DM_NHAN_VIEN!$B$4:$F$18,4,FALSE()) -> Tổ trưởng | F32: 46175 | G32: =CHOOSE(WEEKDAY(F32,2),"Thứ Hai","Thứ Ba","Thứ Tư","Thứ Năm","Thứ Sáu","Thứ Bảy","Chủ Nhật") -> Thứ Ba | H32: =VLOOKUP($B32,DM_NHAN_VIEN!$B$4:$F$18,5,FALSE()) -> Ca Hành Chính | I32: =VLOOKUP($H32,DM_CA_LAM!$A$4:$C$6,2,FALSE()) -> 07:30 | J32: =VLOOKUP($H32,DM_CA_LAM!$A$4:$C$6,3,FALSE()) -> 17:30 | K32: 07:20 | L32: 17:44 | M32: =IF($K32="","",MAX(0,ROUND((TIMEVALUE($K32)-TIMEVALUE($I32))*1440,0))) -> 0 | N32: =IF($L32="","",MAX(0,ROUND((TIMEVALUE($J32)-TIMEVALUE($L32))*1440,0))) -> 0 | O32: =IF(OR($K32="",$L32=""),0,ROUND(VLOOKUP($H32,DM_CA_LAM!$A$4:$F$6,6,FALSE())-$M32/60-$N32/60,2)) -> 8 | P32: Đi làm đủ công | Q32: 0 | T32: =$B32&"_"&TEXT($F32,"yyyymmdd") -> NV029_20260602 | U32: =VLOOKUP($P32,DM_TRANG_THAI!$A$4:$B$9,2,FALSE()) -> P
A33: 30 | B33: NV030 | C33: =VLOOKUP($B33,DM_NHAN_VIEN!$B$4:$F$18,2,FALSE()) -> Tống Văn Thắng | D33: =VLOOKUP($B33,DM_NHAN_VIEN!$B$4:$F$18,3,FALSE()) -> Xưởng sản xuất | E33: =VLOOKUP($B33,DM_NHAN_VIEN!$B$4:$F$18,4,FALSE()) -> Tổ trưởng | F33: 46175 | G33: =CHOOSE(WEEKDAY(F33,2),"Thứ Hai","Thứ Ba","Thứ Tư","Thứ Năm","Thứ Sáu","Thứ Bảy","Chủ Nhật") -> Thứ Ba | H33: =VLOOKUP($B33,DM_NHAN_VIEN!$B$4:$F$18,5,FALSE()) -> Ca Hành Chính | I33: =VLOOKUP($H33,DM_CA_LAM!$A$4:$C$6,2,FALSE()) -> 07:30 | J33: =VLOOKUP($H33,DM_CA_LAM!$A$4:$C$6,3,FALSE()) -> 17:30 | K33: 07:22 | L33: 17:36 | M33: =IF($K33="","",MAX(0,ROUND((TIMEVALUE($K33)-TIMEVALUE($I33))*1440,0))) -> 0 | N33: =IF($L33="","",MAX(0,ROUND((TIMEVALUE($J33)-TIMEVALUE($L33))*1440,0))) -> 0 | O33: =IF(OR($K33="",$L33=""),0,ROUND(VLOOKUP($H33,DM_CA_LAM!$A$4:$F$6,6,FALSE())-$M33/60-$N33/60,2)) -> 8 | P33: Đi làm đủ công | Q33: 0 | T33: =$B33&"_"&TEXT($F33,"yyyymmdd") -> NV030_20260602 | U33: =VLOOKUP($P33,DM_TRANG_THAI!$A$4:$B$9,2,FALSE()) -> P
A34: 31 | B34: NV002 | C34: =VLOOKUP($B34,DM_NHAN_VIEN!$B$4:$F$18,2,FALSE()) -> Nguyễn Văn Giám Đốc | D34: =VLOOKUP($B34,DM_NHAN_VIEN!$B$4:$F$18,3,FALSE()) -> Hành chính | E34: =VLOOKUP($B34,DM_NHAN_VIEN!$B$4:$F$18,4,FALSE()) -> Giám đốc | F34: 46176 | G34: =CHOOSE(WEEKDAY(F34,2),"Thứ Hai","Thứ Ba","Thứ Tư","Thứ Năm","Thứ Sáu","Thứ Bảy","Chủ Nhật") -> Thứ Tư | H34: =VLOOKUP($B34,DM_NHAN_VIEN!$B$4:$F$18,5,FALSE()) -> Ca Hành Chính | I34: =VLOOKUP($H34,DM_CA_LAM!$A$4:$C$6,2,FALSE()) -> 07:30 | J34: =VLOOKUP($H34,DM_CA_LAM!$A$4:$C$6,3,FALSE()) -> 17:30 | K34: 07:21 | L34: 17:36 | M34: =IF($K34="","",MAX(0,ROUND((TIMEVALUE($K34)-TIMEVALUE($I34))*1440,0))) -> 0 | N34: =IF($L34="","",MAX(0,ROUND((TIMEVALUE($J34)-TIMEVALUE($L34))*1440,0))) -> 0 | O34: =IF(OR($K34="",$L34=""),0,ROUND(VLOOKUP($H34,DM_CA_LAM!$A$4:$F$6,6,FALSE())-$M34/60-$N34/60,2)) -> 8 | P34: Đi làm đủ công | Q34: 0 | T34: =$B34&"_"&TEXT($F34,"yyyymmdd") -> NV002_20260603 | U34: =VLOOKUP($P34,DM_TRANG_THAI!$A$4:$B$9,2,FALSE()) -> P
A35: 32 | B35: NV003 | C35: =VLOOKUP($B35,DM_NHAN_VIEN!$B$4:$F$18,2,FALSE()) -> Trần Thị Nhân Sự | D35: =VLOOKUP($B35,DM_NHAN_VIEN!$B$4:$F$18,3,FALSE()) -> Nhân sự | E35: =VLOOKUP($B35,DM_NHAN_VIEN!$B$4:$F$18,4,FALSE()) -> Trưởng phòng | F35: 46176 | G35: =CHOOSE(WEEKDAY(F35,2),"Thứ Hai","Thứ Ba","Thứ Tư","Thứ Năm","Thứ Sáu","Thứ Bảy","Chủ Nhật") -> Thứ Tư | H35: =VLOOKUP($B35,DM_NHAN_VIEN!$B$4:$F$18,5,FALSE()) -> Ca Hành Chính | I35: =VLOOKUP($H35,DM_CA_LAM!$A$4:$C$6,2,FALSE()) -> 07:30 | J35: =VLOOKUP($H35,DM_CA_LAM!$A$4:$C$6,3,FALSE()) -> 17:30 | K35: 07:29 | L35: 17:44 | M35: =IF($K35="","",MAX(0,ROUND((TIMEVALUE($K35)-TIMEVALUE($I35))*1440,0))) -> 0 | N35: =IF($L35="","",MAX(0,ROUND((TIMEVALUE($J35)-TIMEVALUE($L35))*1440,0))) -> 0 | O35: =IF(OR($K35="",$L35=""),0,ROUND(VLOOKUP($H35,DM_CA_LAM!$A$4:$F$6,6,FALSE())-$M35/60-$N35/60,2)) -> 8 | P35: Đi làm đủ công | Q35: 0 | T35: =$B35&"_"&TEXT($F35,"yyyymmdd") -> NV003_20260603 | U35: =VLOOKUP($P35,DM_TRANG_THAI!$A$4:$B$9,2,FALSE()) -> P
A36: 33 | B36: NV004 | C36: =VLOOKUP($B36,DM_NHAN_VIEN!$B$4:$F$18,2,FALSE()) -> Lê Văn Quản Đốc | D36: =VLOOKUP($B36,DM_NHAN_VIEN!$B$4:$F$18,3,FALSE()) -> Xưởng sản xuất | E36: =VLOOKUP($B36,DM_NHAN_VIEN!$B$4:$F$18,4,FALSE()) -> Quản đốc | F36: 46176 | G36: =CHOOSE(WEEKDAY(F36,2),"Thứ Hai","Thứ Ba","Thứ Tư","Thứ Năm","Thứ Sáu","Thứ Bảy","Chủ Nhật") -> Thứ Tư | H36: =VLOOKUP($B36,DM_NHAN_VIEN!$B$4:$F$18,5,FALSE()) -> Ca Hành Chính | I36: =VLOOKUP($H36,DM_CA_LAM!$A$4:$C$6,2,FALSE()) -> 07:30 | J36: =VLOOKUP($H36,DM_CA_LAM!$A$4:$C$6,3,FALSE()) -> 17:30 | K36: 07:22 | L36: 17:38 | M36: =IF($K36="","",MAX(0,ROUND((TIMEVALUE($K36)-TIMEVALUE($I36))*1440,0))) -> 0 | N36: =IF($L36="","",MAX(0,ROUND((TIMEVALUE($J36)-TIMEVALUE($L36))*1440,0))) -> 0 | O36: =IF(OR($K36="",$L36=""),0,ROUND(VLOOKUP($H36,DM_CA_LAM!$A$4:$F$6,6,FALSE())-$M36/60-$N36/60,2)) -> 8 | P36: Đi làm đủ công | Q36: 0 | T36: =$B36&"_"&TEXT($F36,"yyyymmdd") -> NV004_20260603 | U36: =VLOOKUP($P36,DM_TRANG_THAI!$A$4:$B$9,2,FALSE()) -> P
A37: 34 | B37: NV005 | C37: =VLOOKUP($B37,DM_NHAN_VIEN!$B$4:$F$18,2,FALSE()) -> Phạm Công Nhân | D37: =VLOOKUP($B37,DM_NHAN_VIEN!$B$4:$F$18,3,FALSE()) -> Xưởng sản xuất | E37: =VLOOKUP($B37,DM_NHAN_VIEN!$B$4:$F$18,4,FALSE()) -> Công nhân | F37: 46176 | G37: =CHOOSE(WEEKDAY(F37,2),"Thứ Hai","Thứ Ba","Thứ Tư","Thứ Năm","Thứ Sáu","Thứ Bảy","Chủ Nhật") -> Thứ Tư | H37: =VLOOKUP($B37,DM_NHAN_VIEN!$B$4:$F$18,5,FALSE()) -> Ca Hành Chính | I37: =VLOOKUP($H37,DM_CA_LAM!$A$4:$C$6,2,FALSE()) -> 07:30 | J37: =VLOOKUP($H37,DM_CA_LAM!$A$4:$C$6,3,FALSE()) -> 17:30 | K37: 07:21 | L37: 17:33 | M37: =IF($K37="","",MAX(0,ROUND((TIMEVALUE($K37)-TIMEVALUE($I37))*1440,0))) -> 0 | N37: =IF($L37="","",MAX(0,ROUND((TIMEVALUE($J37)-TIMEVALUE($L37))*1440,0))) -> 0 | O37: =IF(OR($K37="",$L37=""),0,ROUND(VLOOKUP($H37,DM_CA_LAM!$A$4:$F$6,6,FALSE())-$M37/60-$N37/60,2)) -> 8 | P37: Đi làm đủ công | Q37: 0 | T37: =$B37&"_"&TEXT($F37,"yyyymmdd") -> NV005_20260603 | U37: =VLOOKUP($P37,DM_TRANG_THAI!$A$4:$B$9,2,FALSE()) -> P
A38: 35 | B38: NV006 | C38: =VLOOKUP($B38,DM_NHAN_VIEN!$B$4:$F$18,2,FALSE()) -> Đỗ Thị Hà | D38: =VLOOKUP($B38,DM_NHAN_VIEN!$B$4:$F$18,3,FALSE()) -> Hành chính | E38: =VLOOKUP($B38,DM_NHAN_VIEN!$B$4:$F$18,4,FALSE()) -> Trưởng phòng | F38: 46176 | G38: =CHOOSE(WEEKDAY(F38,2),"Thứ Hai","Thứ Ba","Thứ Tư","Thứ Năm","Thứ Sáu","Thứ Bảy","Chủ Nhật") -> Thứ Tư | H38: =VLOOKUP($B38,DM_NHAN_VIEN!$B$4:$F$18,5,FALSE()) -> Ca Hành Chính | I38: =VLOOKUP($H38,DM_CA_LAM!$A$4:$C$6,2,FALSE()) -> 07:30 | J38: =VLOOKUP($H38,DM_CA_LAM!$A$4:$C$6,3,FALSE()) -> 17:30 | K38: 07:21 | L38: 17:39 | M38: =IF($K38="","",MAX(0,ROUND((TIMEVALUE($K38)-TIMEVALUE($I38))*1440,0))) -> 0 | N38: =IF($L38="","",MAX(0,ROUND((TIMEVALUE($J38)-TIMEVALUE($L38))*1440,0))) -> 0 | O38: =IF(OR($K38="",$L38=""),0,ROUND(VLOOKUP($H38,DM_CA_LAM!$A$4:$F$6,6,FALSE())-$M38/60-$N38/60,2)) -> 8 | P38: Đi làm đủ công | Q38: 0 | T38: =$B38&"_"&TEXT($F38,"yyyymmdd") -> NV006_20260603 | U38: =VLOOKUP($P38,DM_TRANG_THAI!$A$4:$B$9,2,FALSE()) -> P
A39: 36 | B39: NV007 | C39: =VLOOKUP($B39,DM_NHAN_VIEN!$B$4:$F$18,2,FALSE()) -> Ngô Văn Tài | D39: =VLOOKUP($B39,DM_NHAN_VIEN!$B$4:$F$18,3,FALSE()) -> Hành chính | E39: =VLOOKUP($B39,DM_NHAN_VIEN!$B$4:$F$18,4,FALSE()) -> Phó phòng | F39: 46176 | G39: =CHOOSE(WEEKDAY(F39,2),"Thứ Hai","Thứ Ba","Thứ Tư","Thứ Năm","Thứ Sáu","Thứ Bảy","Chủ Nhật") -> Thứ Tư | H39: =VLOOKUP($B39,DM_NHAN_VIEN!$B$4:$F$18,5,FALSE()) -> Ca Hành Chính | I39: =VLOOKUP($H39,DM_CA_LAM!$A$4:$C$6,2,FALSE()) -> 07:30 | J39: =VLOOKUP($H39,DM_CA_LAM!$A$4:$C$6,3,FALSE()) -> 17:30 | K39: 07:29 | L39: 17:30 | M39: =IF($K39="","",MAX(0,ROUND((TIMEVALUE($K39)-TIMEVALUE($I39))*1440,0))) -> 0 | N39: =IF($L39="","",MAX(0,ROUND((TIMEVALUE($J39)-TIMEVALUE($L39))*1440,0))) -> 0 | O39: =IF(OR($K39="",$L39=""),0,ROUND(VLOOKUP($H39,DM_CA_LAM!$A$4:$F$6,6,FALSE())-$M39/60-$N39/60,2)) -> 8 | P39: Đi làm đủ công | Q39: 0 | T39: =$B39&"_"&TEXT($F39,"yyyymmdd") -> NV007_20260603 | U39: =VLOOKUP($P39,DM_TRANG_THAI!$A$4:$B$9,2,FALSE()) -> P
A40: 37 | B40: NV008 | C40: =VLOOKUP($B40,DM_NHAN_VIEN!$B$4:$F$18,2,FALSE()) -> Vũ Thị Nga | D40: =VLOOKUP($B40,DM_NHAN_VIEN!$B$4:$F$18,3,FALSE()) -> Hành chính | E40: =VLOOKUP($B40,DM_NHAN_VIEN!$B$4:$F$18,4,FALSE()) -> Chuyên viên | F40: 46176 | G40: =CHOOSE(WEEKDAY(F40,2),"Thứ Hai","Thứ Ba","Thứ Tư","Thứ Năm","Thứ Sáu","Thứ Bảy","Chủ Nhật") -> Thứ Tư | H40: =VLOOKUP($B40,DM_NHAN_VIEN!$B$4:$F$18,5,FALSE()) -> Ca Hành Chính | I40: =VLOOKUP($H40,DM_CA_LAM!$A$4:$C$6,2,FALSE()) -> 07:30 | J40: =VLOOKUP($H40,DM_CA_LAM!$A$4:$C$6,3,FALSE()) -> 17:30 | K40: 07:53 | L40: 17:34 | M40: =IF($K40="","",MAX(0,ROUND((TIMEVALUE($K40)-TIMEVALUE($I40))*1440,0))) -> 23 | N40: =IF($L40="","",MAX(0,ROUND((TIMEVALUE($J40)-TIMEVALUE($L40))*1440,0))) -> 0 | O40: =IF(OR($K40="",$L40=""),0,ROUND(VLOOKUP($H40,DM_CA_LAM!$A$4:$F$6,6,FALSE())-$M40/60-$N40/60,2)) -> 7.62 | P40: Đi muộn | Q40: 0 | S40: Họng xe giữa đường | T40: =$B40&"_"&TEXT($F40,"yyyymmdd") -> NV008_20260603 | U40: =VLOOKUP($P40,DM_TRANG_THAI!$A$4:$B$9,2,FALSE()) -> L
A41: 38 | B41: NV010 | C41: =VLOOKUP($B41,DM_NHAN_VIEN!$B$4:$F$18,2,FALSE()) -> Đặng Thị Hồng | D41: =VLOOKUP($B41,DM_NHAN_VIEN!$B$4:$F$18,3,FALSE()) -> Nhân sự | E41: =VLOOKUP($B41,DM_NHAN_VIEN!$B$4:$F$18,4,FALSE()) -> Chuyên viên | F41: 46176 | G41: =CHOOSE(WEEKDAY(F41,2),"Thứ Hai","Thứ Ba","Thứ Tư","Thứ Năm","Thứ Sáu","Thứ Bảy","Chủ Nhật") -> Thứ Tư | H41: =VLOOKUP($B41,DM_NHAN_VIEN!$B$4:$F$18,5,FALSE()) -> Ca Hành Chính | I41: =VLOOKUP($H41,DM_CA_LAM!$A$4:$C$6,2,FALSE()) -> 07:30 | J41: =VLOOKUP($H41,DM_CA_LAM!$A$4:$C$6,3,FALSE()) -> 17:30 | K41: 07:27 | L41: 17:39 | M41: =IF($K41="","",MAX(0,ROUND((TIMEVALUE($K41)-TIMEVALUE($I41))*1440,0))) -> 0 | N41: =IF($L41="","",MAX(0,ROUND((TIMEVALUE($J41)-TIMEVALUE($L41))*1440,0))) -> 0 | O41: =IF(OR($K41="",$L41=""),0,ROUND(VLOOKUP($H41,DM_CA_LAM!$A$4:$F$6,6,FALSE())-$M41/60-$N41/60,2)) -> 8 | P41: Đi làm đủ công | Q41: 0 | T41: =$B41&"_"&TEXT($F41,"yyyymmdd") -> NV010_20260603 | U41: =VLOOKUP($P41,DM_TRANG_THAI!$A$4:$B$9,2,FALSE()) -> P
A42: 39 | B42: NV011 | C42: =VLOOKUP($B42,DM_NHAN_VIEN!$B$4:$F$18,2,FALSE()) -> Chu Văn Minh | D42: =VLOOKUP($B42,DM_NHAN_VIEN!$B$4:$F$18,3,FALSE()) -> Nhân sự | E42: =VLOOKUP($B42,DM_NHAN_VIEN!$B$4:$F$18,4,FALSE()) -> Chuyên viên | F42: 46176 | G42: =CHOOSE(WEEKDAY(F42,2),"Thứ Hai","Thứ Ba","Thứ Tư","Thứ Năm","Thứ Sáu","Thứ Bảy","Chủ Nhật") -> Thứ Tư | H42: =VLOOKUP($B42,DM_NHAN_VIEN!$B$4:$F$18,5,FALSE()) -> Ca Hành Chính | I42: =VLOOKUP($H42,DM_CA_LAM!$A$4:$C$6,2,FALSE()) -> 07:30 | J42: =VLOOKUP($H42,DM_CA_LAM!$A$4:$C$6,3,FALSE()) -> 17:30 | K42: 07:27 | L42: 17:44 | M42: =IF($K42="","",MAX(0,ROUND((TIMEVALUE($K42)-TIMEVALUE($I42))*1440,0))) -> 0 | N42: =IF($L42="","",MAX(0,ROUND((TIMEVALUE($J42)-TIMEVALUE($L42))*1440,0))) -> 0 | O42: =IF(OR($K42="",$L42=""),0,ROUND(VLOOKUP($H42,DM_CA_LAM!$A$4:$F$6,6,FALSE())-$M42/60-$N42/60,2)) -> 8 | P42: Đi làm đủ công | Q42: 0 | T42: =$B42&"_"&TEXT($F42,"yyyymmdd") -> NV011_20260603 | U42: =VLOOKUP($P42,DM_TRANG_THAI!$A$4:$B$9,2,FALSE()) -> P
A43: 40 | B43: NV014 | C43: =VLOOKUP($B43,DM_NHAN_VIEN!$B$4:$F$18,2,FALSE()) -> Phan Thị Khánh | D43: =VLOOKUP($B43,DM_NHAN_VIEN!$B$4:$F$18,3,FALSE()) -> Kế toán | E43: =VLOOKUP($B43,DM_NHAN_VIEN!$B$4:$F$18,4,FALSE()) -> Trưởng phòng | F43: 46176 | G43: =CHOOSE(WEEKDAY(F43,2),"Thứ Hai","Thứ Ba","Thứ Tư","Thứ Năm","Thứ Sáu","Thứ Bảy","Chủ Nhật") -> Thứ Tư | H43: =VLOOKUP($B43,DM_NHAN_VIEN!$B$4:$F$18,5,FALSE()) -> Ca Hành Chính | I43: =VLOOKUP($H43,DM_CA_LAM!$A$4:$C$6,2,FALSE()) -> 07:30 | J43: =VLOOKUP($H43,DM_CA_LAM!$A$4:$C$6,3,FALSE()) -> 17:30 | K43: 07:30 | L43: 17:39 | M43: =IF($K43="","",MAX(0,ROUND((TIMEVALUE($K43)-TIMEVALUE($I43))*1440,0))) -> 0 | N43: =IF($L43="","",MAX(0,ROUND((TIMEVALUE($J43)-TIMEVALUE($L43))*1440,0))) -> 0 | O43: =IF(OR($K43="",$L43=""),0,ROUND(VLOOKUP($H43,DM_CA_LAM!$A$4:$F$6,6,FALSE())-$M43/60-$N43/60,2)) -> 8 | P43: Đi làm đủ công | Q43: 0 | T43: =$B43&"_"&TEXT($F43,"yyyymmdd") -> NV014_20260603 | U43: =VLOOKUP($P43,DM_TRANG_THAI!$A$4:$B$9,2,FALSE()) -> P
A44: 41 | B44: NV015 | C44: =VLOOKUP($B44,DM_NHAN_VIEN!$B$4:$F$18,2,FALSE()) -> Trịnh Văn Hùng | D44: =VLOOKUP($B44,DM_NHAN_VIEN!$B$4:$F$18,3,FALSE()) -> Kế toán | E44: =VLOOKUP($B44,DM_NHAN_VIEN!$B$4:$F$18,4,FALSE()) -> Phó phòng | F44: 46176 | G44: =CHOOSE(WEEKDAY(F44,2),"Thứ Hai","Thứ Ba","Thứ Tư","Thứ Năm","Thứ Sáu","Thứ Bảy","Chủ Nhật") -> Thứ Tư | H44: =VLOOKUP($B44,DM_NHAN_VIEN!$B$4:$F$18,5,FALSE()) -> Ca Hành Chính | I44: =VLOOKUP($H44,DM_CA_LAM!$A$4:$C$6,2,FALSE()) -> 07:30 | J44: =VLOOKUP($H44,DM_CA_LAM!$A$4:$C$6,3,FALSE()) -> 17:30 | K44: 07:30 | L44: 17:38 | M44: =IF($K44="","",MAX(0,ROUND((TIMEVALUE($K44)-TIMEVALUE($I44))*1440,0))) -> 0 | N44: =IF($L44="","",MAX(0,ROUND((TIMEVALUE($J44)-TIMEVALUE($L44))*1440,0))) -> 0 | O44: =IF(OR($K44="",$L44=""),0,ROUND(VLOOKUP($H44,DM_CA_LAM!$A$4:$F$6,6,FALSE())-$M44/60-$N44/60,2)) -> 8 | P44: Đi làm đủ công | Q44: 0 | T44: =$B44&"_"&TEXT($F44,"yyyymmdd") -> NV015_20260603 | U44: =VLOOKUP($P44,DM_TRANG_THAI!$A$4:$B$9,2,FALSE()) -> P
...

Sheet BANG_CONG_THANG
A1: BẢNG CÔNG TỔNG HỢP - THÁNG 06/2026
A2: Mỗi ngày lấy tự động từ sheet CHI_TIET_CHAM_CONG | Mã: P=đi làm, L=đi muộn, A=vắng, NP=nghỉ phép, KL=nghỉ không lương, CN=Chủ Nhật
A3: STT | B3: Mã NV | C3: Họ và tên | D3: Phòng ban | E3: Ca làm chính | F3: 1 | G3: 2 | H3: 3 | I3: 4 | J3: 5 | K3: 6 | L3: 7 | M3: 8 | N3: 9 | O3: 10 | P3: 11 | Q3: 12 | R3: 13 | S3: 14 | T3: 15 | U3: 16 | V3: 17 | W3: 18 | X3: 19 | Y3: 20 | Z3: 21 | AA3: 22 | AB3: 23 | AC3: 24 | AD3: 25 | AE3: 26 | AF3: 27 | AG3: 28 | AH3: 29 | AI3: 30 | AJ3: Tổng ngày công | AK3: Số ngày đi muộn | AL3: Số ngày vắng | AM3: Số ngày nghỉ phép/KL | AN3: Tổng giờ OT
F4: T2 | G4: T3 | H4: T4 | I4: T5 | J4: T6 | K4: T7 | L4: CN | M4: T2 | N4: T3 | O4: T4 | P4: T5 | Q4: T6 | R4: T7 | S4: CN | T4: T2 | U4: T3 | V4: T4 | W4: T5 | X4: T6 | Y4: T7 | Z4: CN | AA4: T2 | AB4: T3 | AC4: T4 | AD4: T5 | AE4: T6 | AF4: T7 | AG4: CN | AH4: T2 | AI4: T3
A5: 1 | B5: NV002 | C5: =DM_NHAN_VIEN!C4 -> Nguyễn Văn Giám Đốc | D5: =DM_NHAN_VIEN!D4 -> Hành chính | E5: =DM_NHAN_VIEN!F4 -> Ca Hành Chính | F5: =IFERROR(VLOOKUP($B5&"_"&TEXT(DATE(2026,6,1),"yyyymmdd"),CHI_TIET_CHAM_CONG!$T:$U,2,FALSE()),"") -> P | G5: =IFERROR(VLOOKUP($B5&"_"&TEXT(DATE(2026,6,2),"yyyymmdd"),CHI_TIET_CHAM_CONG!$T:$U,2,FALSE()),"") -> P | H5: =IFERROR(VLOOKUP($B5&"_"&TEXT(DATE(2026,6,3),"yyyymmdd"),CHI_TIET_CHAM_CONG!$T:$U,2,FALSE()),"") -> P | I5: =IFERROR(VLOOKUP($B5&"_"&TEXT(DATE(2026,6,4),"yyyymmdd"),CHI_TIET_CHAM_CONG!$T:$U,2,FALSE()),"") -> P | J5: =IFERROR(VLOOKUP($B5&"_"&TEXT(DATE(2026,6,5),"yyyymmdd"),CHI_TIET_CHAM_CONG!$T:$U,2,FALSE()),"") -> P | K5: =IFERROR(VLOOKUP($B5&"_"&TEXT(DATE(2026,6,6),"yyyymmdd"),CHI_TIET_CHAM_CONG!$T:$U,2,FALSE()),"") -> P | L5: CN | M5: =IFERROR(VLOOKUP($B5&"_"&TEXT(DATE(2026,6,8),"yyyymmdd"),CHI_TIET_CHAM_CONG!$T:$U,2,FALSE()),"") -> P | N5: =IFERROR(VLOOKUP($B5&"_"&TEXT(DATE(2026,6,9),"yyyymmdd"),CHI_TIET_CHAM_CONG!$T:$U,2,FALSE()),"") -> P | O5: =IFERROR(VLOOKUP($B5&"_"&TEXT(DATE(2026,6,10),"yyyymmdd"),CHI_TIET_CHAM_CONG!$T:$U,2,FALSE()),"") -> P | P5: =IFERROR(VLOOKUP($B5&"_"&TEXT(DATE(2026,6,11),"yyyymmdd"),CHI_TIET_CHAM_CONG!$T:$U,2,FALSE()),"") -> KL | Q5: =IFERROR(VLOOKUP($B5&"_"&TEXT(DATE(2026,6,12),"yyyymmdd"),CHI_TIET_CHAM_CONG!$T:$U,2,FALSE()),"") -> P | R5: =IFERROR(VLOOKUP($B5&"_"&TEXT(DATE(2026,6,13),"yyyymmdd"),CHI_TIET_CHAM_CONG!$T:$U,2,FALSE()),"") -> P | S5: CN | T5: =IFERROR(VLOOKUP($B5&"_"&TEXT(DATE(2026,6,15),"yyyymmdd"),CHI_TIET_CHAM_CONG!$T:$U,2,FALSE()),"") -> P | U5: =IFERROR(VLOOKUP($B5&"_"&TEXT(DATE(2026,6,16),"yyyymmdd"),CHI_TIET_CHAM_CONG!$T:$U,2,FALSE()),"") -> L | V5: =IFERROR(VLOOKUP($B5&"_"&TEXT(DATE(2026,6,17),"yyyymmdd"),CHI_TIET_CHAM_CONG!$T:$U,2,FALSE()),"") -> P | W5: =IFERROR(VLOOKUP($B5&"_"&TEXT(DATE(2026,6,18),"yyyymmdd"),CHI_TIET_CHAM_CONG!$T:$U,2,FALSE()),"") -> P | X5: =IFERROR(VLOOKUP($B5&"_"&TEXT(DATE(2026,6,19),"yyyymmdd"),CHI_TIET_CHAM_CONG!$T:$U,2,FALSE()),"") -> P | Y5: =IFERROR(VLOOKUP($B5&"_"&TEXT(DATE(2026,6,20),"yyyymmdd"),CHI_TIET_CHAM_CONG!$T:$U,2,FALSE()),"") -> P | Z5: CN | AA5: =IFERROR(VLOOKUP($B5&"_"&TEXT(DATE(2026,6,22),"yyyymmdd"),CHI_TIET_CHAM_CONG!$T:$U,2,FALSE()),"") -> L | AB5: =IFERROR(VLOOKUP($B5&"_"&TEXT(DATE(2026,6,23),"yyyymmdd"),CHI_TIET_CHAM_CONG!$T:$U,2,FALSE()),"") -> L | AC5: =IFERROR(VLOOKUP($B5&"_"&TEXT(DATE(2026,6,24),"yyyymmdd"),CHI_TIET_CHAM_CONG!$T:$U,2,FALSE()),"") -> NP | AD5: =IFERROR(VLOOKUP($B5&"_"&TEXT(DATE(2026,6,25),"yyyymmdd"),CHI_TIET_CHAM_CONG!$T:$U,2,FALSE()),"") -> L | AE5: =IFERROR(VLOOKUP($B5&"_"&TEXT(DATE(2026,6,26),"yyyymmdd"),CHI_TIET_CHAM_CONG!$T:$U,2,FALSE()),"") -> A | AF5: =IFERROR(VLOOKUP($B5&"_"&TEXT(DATE(2026,6,27),"yyyymmdd"),CHI_TIET_CHAM_CONG!$T:$U,2,FALSE()),"") -> P | AG5: CN | AH5: =IFERROR(VLOOKUP($B5&"_"&TEXT(DATE(2026,6,29),"yyyymmdd"),CHI_TIET_CHAM_CONG!$T:$U,2,FALSE()),"") -> P | AI5: =IFERROR(VLOOKUP($B5&"_"&TEXT(DATE(2026,6,30),"yyyymmdd"),CHI_TIET_CHAM_CONG!$T:$U,2,FALSE()),"") -> P | AJ5: =COUNTIF(F5:AI5,"P")+COUNTIF(F5:AI5,"L") -> 23 | AK5: =COUNTIF(F5:AI5,"L") -> 4 | AL5: =COUNTIF(F5:AI5,"A") -> 1 | AM5: =COUNTIF(F5:AI5,"NP")+COUNTIF(F5:AI5,"KL") -> 2 | AN5: =SUMIF(CHI_TIET_CHAM_CONG!$B:$B,$B5,CHI_TIET_CHAM_CONG!$Q:$Q) -> 2
A6: 2 | B6: NV003 | C6: =DM_NHAN_VIEN!C5 -> Trần Thị Nhân Sự | D6: =DM_NHAN_VIEN!D5 -> Nhân sự | E6: =DM_NHAN_VIEN!F5 -> Ca Hành Chính | F6: =IFERROR(VLOOKUP($B6&"_"&TEXT(DATE(2026,6,1),"yyyymmdd"),CHI_TIET_CHAM_CONG!$T:$U,2,FALSE()),"") -> P | G6: =IFERROR(VLOOKUP($B6&"_"&TEXT(DATE(2026,6,2),"yyyymmdd"),CHI_TIET_CHAM_CONG!$T:$U,2,FALSE()),"") -> P | H6: =IFERROR(VLOOKUP($B6&"_"&TEXT(DATE(2026,6,3),"yyyymmdd"),CHI_TIET_CHAM_CONG!$T:$U,2,FALSE()),"") -> P | I6: =IFERROR(VLOOKUP($B6&"_"&TEXT(DATE(2026,6,4),"yyyymmdd"),CHI_TIET_CHAM_CONG!$T:$U,2,FALSE()),"") -> KL | J6: =IFERROR(VLOOKUP($B6&"_"&TEXT(DATE(2026,6,5),"yyyymmdd"),CHI_TIET_CHAM_CONG!$T:$U,2,FALSE()),"") -> L | K6: =IFERROR(VLOOKUP($B6&"_"&TEXT(DATE(2026,6,6),"yyyymmdd"),CHI_TIET_CHAM_CONG!$T:$U,2,FALSE()),"") -> P | L6: CN | M6: =IFERROR(VLOOKUP($B6&"_"&TEXT(DATE(2026,6,8),"yyyymmdd"),CHI_TIET_CHAM_CONG!$T:$U,2,FALSE()),"") -> P | N6: =IFERROR(VLOOKUP($B6&"_"&TEXT(DATE(2026,6,9),"yyyymmdd"),CHI_TIET_CHAM_CONG!$T:$U,2,FALSE()),"") -> P | O6: =IFERROR(VLOOKUP($B6&"_"&TEXT(DATE(2026,6,10),"yyyymmdd"),CHI_TIET_CHAM_CONG!$T:$U,2,FALSE()),"") -> P | P6: =IFERROR(VLOOKUP($B6&"_"&TEXT(DATE(2026,6,11),"yyyymmdd"),CHI_TIET_CHAM_CONG!$T:$U,2,FALSE()),"") -> P | Q6: =IFERROR(VLOOKUP($B6&"_"&TEXT(DATE(2026,6,12),"yyyymmdd"),CHI_TIET_CHAM_CONG!$T:$U,2,FALSE()),"") -> P | R6: =IFERROR(VLOOKUP($B6&"_"&TEXT(DATE(2026,6,13),"yyyymmdd"),CHI_TIET_CHAM_CONG!$T:$U,2,FALSE()),"") -> L | S6: CN | T6: =IFERROR(VLOOKUP($B6&"_"&TEXT(DATE(2026,6,15),"yyyymmdd"),CHI_TIET_CHAM_CONG!$T:$U,2,FALSE()),"") -> P | U6: =IFERROR(VLOOKUP($B6&"_"&TEXT(DATE(2026,6,16),"yyyymmdd"),CHI_TIET_CHAM_CONG!$T:$U,2,FALSE()),"") -> L | V6: =IFERROR(VLOOKUP($B6&"_"&TEXT(DATE(2026,6,17),"yyyymmdd"),CHI_TIET_CHAM_CONG!$T:$U,2,FALSE()),"") -> P | W6: =IFERROR(VLOOKUP($B6&"_"&TEXT(DATE(2026,6,18),"yyyymmdd"),CHI_TIET_CHAM_CONG!$T:$U,2,FALSE()),"") -> L | X6: =IFERROR(VLOOKUP($B6&"_"&TEXT(DATE(2026,6,19),"yyyymmdd"),CHI_TIET_CHAM_CONG!$T:$U,2,FALSE()),"") -> P | Y6: =IFERROR(VLOOKUP($B6&"_"&TEXT(DATE(2026,6,20),"yyyymmdd"),CHI_TIET_CHAM_CONG!$T:$U,2,FALSE()),"") -> P | Z6: CN | AA6: =IFERROR(VLOOKUP($B6&"_"&TEXT(DATE(2026,6,22),"yyyymmdd"),CHI_TIET_CHAM_CONG!$T:$U,2,FALSE()),"") -> P | AB6: =IFERROR(VLOOKUP($B6&"_"&TEXT(DATE(2026,6,23),"yyyymmdd"),CHI_TIET_CHAM_CONG!$T:$U,2,FALSE()),"") -> P | AC6: =IFERROR(VLOOKUP($B6&"_"&TEXT(DATE(2026,6,24),"yyyymmdd"),CHI_TIET_CHAM_CONG!$T:$U,2,FALSE()),"") -> A | AD6: =IFERROR(VLOOKUP($B6&"_"&TEXT(DATE(2026,6,25),"yyyymmdd"),CHI_TIET_CHAM_CONG!$T:$U,2,FALSE()),"") -> P | AE6: =IFERROR(VLOOKUP($B6&"_"&TEXT(DATE(2026,6,26),"yyyymmdd"),CHI_TIET_CHAM_CONG!$T:$U,2,FALSE()),"") -> P | AF6: =IFERROR(VLOOKUP($B6&"_"&TEXT(DATE(2026,6,27),"yyyymmdd"),CHI_TIET_CHAM_CONG!$T:$U,2,FALSE()),"") -> P | AG6: CN | AH6: =IFERROR(VLOOKUP($B6&"_"&TEXT(DATE(2026,6,29),"yyyymmdd"),CHI_TIET_CHAM_CONG!$T:$U,2,FALSE()),"") -> P | AI6: =IFERROR(VLOOKUP($B6&"_"&TEXT(DATE(2026,6,30),"yyyymmdd"),CHI_TIET_CHAM_CONG!$T:$U,2,FALSE()),"") -> KL | AJ6: =COUNTIF(F6:AI6,"P")+COUNTIF(F6:AI6,"L") -> 23 | AK6: =COUNTIF(F6:AI6,"L") -> 4 | AL6: =COUNTIF(F6:AI6,"A") -> 1 | AM6: =COUNTIF(F6:AI6,"NP")+COUNTIF(F6:AI6,"KL") -> 2 | AN6: =SUMIF(CHI_TIET_CHAM_CONG!$B:$B,$B6,CHI_TIET_CHAM_CONG!$Q:$Q) -> 5
A7: 3 | B7: NV004 | C7: =DM_NHAN_VIEN!C6 -> Lê Văn Quản Đốc | D7: =DM_NHAN_VIEN!D6 -> Xưởng sản xuất | E7: =DM_NHAN_VIEN!F6 -> Ca Hành Chính | F7: =IFERROR(VLOOKUP($B7&"_"&TEXT(DATE(2026,6,1),"yyyymmdd"),CHI_TIET_CHAM_CONG!$T:$U,2,FALSE()),"") -> P | G7: =IFERROR(VLOOKUP($B7&"_"&TEXT(DATE(2026,6,2),"yyyymmdd"),CHI_TIET_CHAM_CONG!$T:$U,2,FALSE()),"") -> P | H7: =IFERROR(VLOOKUP($B7&"_"&TEXT(DATE(2026,6,3),"yyyymmdd"),CHI_TIET_CHAM_CONG!$T:$U,2,FALSE()),"") -> P | I7: =IFERROR(VLOOKUP($B7&"_"&TEXT(DATE(2026,6,4),"yyyymmdd"),CHI_TIET_CHAM_CONG!$T:$U,2,FALSE()),"") -> L | J7: =IFERROR(VLOOKUP($B7&"_"&TEXT(DATE(2026,6,5),"yyyymmdd"),CHI_TIET_CHAM_CONG!$T:$U,2,FALSE()),"") -> NP | K7: =IFERROR(VLOOKUP($B7&"_"&TEXT(DATE(2026,6,6),"yyyymmdd"),CHI_TIET_CHAM_CONG!$T:$U,2,FALSE()),"") -> A | L7: CN | M7: =IFERROR(VLOOKUP($B7&"_"&TEXT(DATE(2026,6,8),"yyyymmdd"),CHI_TIET_CHAM_CONG!$T:$U,2,FALSE()),"") -> P | N7: =IFERROR(VLOOKUP($B7&"_"&TEXT(DATE(2026,6,9),"yyyymmdd"),CHI_TIET_CHAM_CONG!$T:$U,2,FALSE()),"") -> P | O7: =IFERROR(VLOOKUP($B7&"_"&TEXT(DATE(2026,6,10),"yyyymmdd"),CHI_TIET_CHAM_CONG!$T:$U,2,FALSE()),"") -> KL | P7: =IFERROR(VLOOKUP($B7&"_"&TEXT(DATE(2026,6,11),"yyyymmdd"),CHI_TIET_CHAM_CONG!$T:$U,2,FALSE()),"") -> P | Q7: =IFERROR(VLOOKUP($B7&"_"&TEXT(DATE(2026,6,12),"yyyymmdd"),CHI_TIET_CHAM_CONG!$T:$U,2,FALSE()),"") -> NP | R7: =IFERROR(VLOOKUP($B7&"_"&TEXT(DATE(2026,6,13),"yyyymmdd"),CHI_TIET_CHAM_CONG!$T:$U,2,FALSE()),"") -> KL | S7: CN | T7: =IFERROR(VLOOKUP($B7&"_"&TEXT(DATE(2026,6,15),"yyyymmdd"),CHI_TIET_CHAM_CONG!$T:$U,2,FALSE()),"") -> P | U7: =IFERROR(VLOOKUP($B7&"_"&TEXT(DATE(2026,6,16),"yyyymmdd"),CHI_TIET_CHAM_CONG!$T:$U,2,FALSE()),"") -> P | V7: =IFERROR(VLOOKUP($B7&"_"&TEXT(DATE(2026,6,17),"yyyymmdd"),CHI_TIET_CHAM_CONG!$T:$U,2,FALSE()),"") -> P | W7: =IFERROR(VLOOKUP($B7&"_"&TEXT(DATE(2026,6,18),"yyyymmdd"),CHI_TIET_CHAM_CONG!$T:$U,2,FALSE()),"") -> L | X7: =IFERROR(VLOOKUP($B7&"_"&TEXT(DATE(2026,6,19),"yyyymmdd"),CHI_TIET_CHAM_CONG!$T:$U,2,FALSE()),"") -> P | Y7: =IFERROR(VLOOKUP($B7&"_"&TEXT(DATE(2026,6,20),"yyyymmdd"),CHI_TIET_CHAM_CONG!$T:$U,2,FALSE()),"") -> NP | Z7: CN | AA7: =IFERROR(VLOOKUP($B7&"_"&TEXT(DATE(2026,6,22),"yyyymmdd"),CHI_TIET_CHAM_CONG!$T:$U,2,FALSE()),"") -> P | AB7: =IFERROR(VLOOKUP($B7&"_"&TEXT(DATE(2026,6,23),"yyyymmdd"),CHI_TIET_CHAM_CONG!$T:$U,2,FALSE()),"") -> P | AC7: =IFERROR(VLOOKUP($B7&"_"&TEXT(DATE(2026,6,24),"yyyymmdd"),CHI_TIET_CHAM_CONG!$T:$U,2,FALSE()),"") -> P | AD7: =IFERROR(VLOOKUP($B7&"_"&TEXT(DATE(2026,6,25),"yyyymmdd"),CHI_TIET_CHAM_CONG!$T:$U,2,FALSE()),"") -> P | AE7: =IFERROR(VLOOKUP($B7&"_"&TEXT(DATE(2026,6,26),"yyyymmdd"),CHI_TIET_CHAM_CONG!$T:$U,2,FALSE()),"") -> A | AF7: =IFERROR(VLOOKUP($B7&"_"&TEXT(DATE(2026,6,27),"yyyymmdd"),CHI_TIET_CHAM_CONG!$T:$U,2,FALSE()),"") -> P | AG7: CN | AH7: =IFERROR(VLOOKUP($B7&"_"&TEXT(DATE(2026,6,29),"yyyymmdd"),CHI_TIET_CHAM_CONG!$T:$U,2,FALSE()),"") -> P | AI7: =IFERROR(VLOOKUP($B7&"_"&TEXT(DATE(2026,6,30),"yyyymmdd"),CHI_TIET_CHAM_CONG!$T:$U,2,FALSE()),"") -> P | AJ7: =COUNTIF(F7:AI7,"P")+COUNTIF(F7:AI7,"L") -> 19 | AK7: =COUNTIF(F7:AI7,"L") -> 2 | AL7: =COUNTIF(F7:AI7,"A") -> 2 | AM7: =COUNTIF(F7:AI7,"NP")+COUNTIF(F7:AI7,"KL") -> 5 | AN7: =SUMIF(CHI_TIET_CHAM_CONG!$B:$B,$B7,CHI_TIET_CHAM_CONG!$Q:$Q) -> 4.5
A8: 4 | B8: NV005 | C8: =DM_NHAN_VIEN!C7 -> Phạm Công Nhân | D8: =DM_NHAN_VIEN!D7 -> Xưởng sản xuất | E8: =DM_NHAN_VIEN!F7 -> Ca Hành Chính | F8: =IFERROR(VLOOKUP($B8&"_"&TEXT(DATE(2026,6,1),"yyyymmdd"),CHI_TIET_CHAM_CONG!$T:$U,2,FALSE()),"") -> P | G8: =IFERROR(VLOOKUP($B8&"_"&TEXT(DATE(2026,6,2),"yyyymmdd"),CHI_TIET_CHAM_CONG!$T:$U,2,FALSE()),"") -> P | H8: =IFERROR(VLOOKUP($B8&"_"&TEXT(DATE(2026,6,3),"yyyymmdd"),CHI_TIET_CHAM_CONG!$T:$U,2,FALSE()),"") -> P | I8: =IFERROR(VLOOKUP($B8&"_"&TEXT(DATE(2026,6,4),"yyyymmdd"),CHI_TIET_CHAM_CONG!$T:$U,2,FALSE()),"") -> P | J8: =IFERROR(VLOOKUP($B8&"_"&TEXT(DATE(2026,6,5),"yyyymmdd"),CHI_TIET_CHAM_CONG!$T:$U,2,FALSE()),"") -> P | K8: =IFERROR(VLOOKUP($B8&"_"&TEXT(DATE(2026,6,6),"yyyymmdd"),CHI_TIET_CHAM_CONG!$T:$U,2,FALSE()),"") -> P | L8: CN | M8: =IFERROR(VLOOKUP($B8&"_"&TEXT(DATE(2026,6,8),"yyyymmdd"),CHI_TIET_CHAM_CONG!$T:$U,2,FALSE()),"") -> L | N8: =IFERROR(VLOOKUP($B8&"_"&TEXT(DATE(2026,6,9),"yyyymmdd"),CHI_TIET_CHAM_CONG!$T:$U,2,FALSE()),"") -> P | O8: =IFERROR(VLOOKUP($B8&"_"&TEXT(DATE(2026,6,10),"yyyymmdd"),CHI_TIET_CHAM_CONG!$T:$U,2,FALSE()),"") -> P | P8: =IFERROR(VLOOKUP($B8&"_"&TEXT(DATE(2026,6,11),"yyyymmdd"),CHI_TIET_CHAM_CONG!$T:$U,2,FALSE()),"") -> P | Q8: =IFERROR(VLOOKUP($B8&"_"&TEXT(DATE(2026,6,12),"yyyymmdd"),CHI_TIET_CHAM_CONG!$T:$U,2,FALSE()),"") -> P | R8: =IFERROR(VLOOKUP($B8&"_"&TEXT(DATE(2026,6,13),"yyyymmdd"),CHI_TIET_CHAM_CONG!$T:$U,2,FALSE()),"") -> P | S8: CN | T8: =IFERROR(VLOOKUP($B8&"_"&TEXT(DATE(2026,6,15),"yyyymmdd"),CHI_TIET_CHAM_CONG!$T:$U,2,FALSE()),"") -> P | U8: =IFERROR(VLOOKUP($B8&"_"&TEXT(DATE(2026,6,16),"yyyymmdd"),CHI_TIET_CHAM_CONG!$T:$U,2,FALSE()),"") -> P | V8: =IFERROR(VLOOKUP($B8&"_"&TEXT(DATE(2026,6,17),"yyyymmdd"),CHI_TIET_CHAM_CONG!$T:$U,2,FALSE()),"") -> P | W8: =IFERROR(VLOOKUP($B8&"_"&TEXT(DATE(2026,6,18),"yyyymmdd"),CHI_TIET_CHAM_CONG!$T:$U,2,FALSE()),"") -> L | X8: =IFERROR(VLOOKUP($B8&"_"&TEXT(DATE(2026,6,19),"yyyymmdd"),CHI_TIET_CHAM_CONG!$T:$U,2,FALSE()),"") -> P | Y8: =IFERROR(VLOOKUP($B8&"_"&TEXT(DATE(2026,6,20),"yyyymmdd"),CHI_TIET_CHAM_CONG!$T:$U,2,FALSE()),"") -> P | Z8: CN | AA8: =IFERROR(VLOOKUP($B8&"_"&TEXT(DATE(2026,6,22),"yyyymmdd"),CHI_TIET_CHAM_CONG!$T:$U,2,FALSE()),"") -> P | AB8: =IFERROR(VLOOKUP($B8&"_"&TEXT(DATE(2026,6,23),"yyyymmdd"),CHI_TIET_CHAM_CONG!$T:$U,2,FALSE()),"") -> P | AC8: =IFERROR(VLOOKUP($B8&"_"&TEXT(DATE(2026,6,24),"yyyymmdd"),CHI_TIET_CHAM_CONG!$T:$U,2,FALSE()),"") -> P | AD8: =IFERROR(VLOOKUP($B8&"_"&TEXT(DATE(2026,6,25),"yyyymmdd"),CHI_TIET_CHAM_CONG!$T:$U,2,FALSE()),"") -> P | AE8: =IFERROR(VLOOKUP($B8&"_"&TEXT(DATE(2026,6,26),"yyyymmdd"),CHI_TIET_CHAM_CONG!$T:$U,2,FALSE()),"") -> KL | AF8: =IFERROR(VLOOKUP($B8&"_"&TEXT(DATE(2026,6,27),"yyyymmdd"),CHI_TIET_CHAM_CONG!$T:$U,2,FALSE()),"") -> P | AG8: CN | AH8: =IFERROR(VLOOKUP($B8&"_"&TEXT(DATE(2026,6,29),"yyyymmdd"),CHI_TIET_CHAM_CONG!$T:$U,2,FALSE()),"") -> P | AI8: =IFERROR(VLOOKUP($B8&"_"&TEXT(DATE(2026,6,30),"yyyymmdd"),CHI_TIET_CHAM_CONG!$T:$U,2,FALSE()),"") -> P | AJ8: =COUNTIF(F8:AI8,"P")+COUNTIF(F8:AI8,"L") -> 25 | AK8: =COUNTIF(F8:AI8,"L") -> 2 | AL8: =COUNTIF(F8:AI8,"A") -> 0 | AM8: =COUNTIF(F8:AI8,"NP")+COUNTIF(F8:AI8,"KL") -> 1 | AN8: =SUMIF(CHI_TIET_CHAM_CONG!$B:$B,$B8,CHI_TIET_CHAM_CONG!$Q:$Q) -> 3
A9: 5 | B9: NV006 | C9: =DM_NHAN_VIEN!C8 -> Đỗ Thị Hà | D9: =DM_NHAN_VIEN!D8 -> Hành chính | E9: =DM_NHAN_VIEN!F8 -> Ca Hành Chính | F9: =IFERROR(VLOOKUP($B9&"_"&TEXT(DATE(2026,6,1),"yyyymmdd"),CHI_TIET_CHAM_CONG!$T:$U,2,FALSE()),"") -> P | G9: =IFERROR(VLOOKUP($B9&"_"&TEXT(DATE(2026,6,2),"yyyymmdd"),CHI_TIET_CHAM_CONG!$T:$U,2,FALSE()),"") -> P | H9: =IFERROR(VLOOKUP($B9&"_"&TEXT(DATE(2026,6,3),"yyyymmdd"),CHI_TIET_CHAM_CONG!$T:$U,2,FALSE()),"") -> P | I9: =IFERROR(VLOOKUP($B9&"_"&TEXT(DATE(2026,6,4),"yyyymmdd"),CHI_TIET_CHAM_CONG!$T:$U,2,FALSE()),"") -> P | J9: =IFERROR(VLOOKUP($B9&"_"&TEXT(DATE(2026,6,5),"yyyymmdd"),CHI_TIET_CHAM_CONG!$T:$U,2,FALSE()),"") -> P | K9: =IFERROR(VLOOKUP($B9&"_"&TEXT(DATE(2026,6,6),"yyyymmdd"),CHI_TIET_CHAM_CONG!$T:$U,2,FALSE()),"") -> P | L9: CN | M9: =IFERROR(VLOOKUP($B9&"_"&TEXT(DATE(2026,6,8),"yyyymmdd"),CHI_TIET_CHAM_CONG!$T:$U,2,FALSE()),"") -> L | N9: =IFERROR(VLOOKUP($B9&"_"&TEXT(DATE(2026,6,9),"yyyymmdd"),CHI_TIET_CHAM_CONG!$T:$U,2,FALSE()),"") -> P | O9: =IFERROR(VLOOKUP($B9&"_"&TEXT(DATE(2026,6,10),"yyyymmdd"),CHI_TIET_CHAM_CONG!$T:$U,2,FALSE()),"") -> P | P9: =IFERROR(VLOOKUP($B9&"_"&TEXT(DATE(2026,6,11),"yyyymmdd"),CHI_TIET_CHAM_CONG!$T:$U,2,FALSE()),"") -> NP | Q9: =IFERROR(VLOOKUP($B9&"_"&TEXT(DATE(2026,6,12),"yyyymmdd"),CHI_TIET_CHAM_CONG!$T:$U,2,FALSE()),"") -> P | R9: =IFERROR(VLOOKUP($B9&"_"&TEXT(DATE(2026,6,13),"yyyymmdd"),CHI_TIET_CHAM_CONG!$T:$U,2,FALSE()),"") -> P | S9: CN | T9: =IFERROR(VLOOKUP($B9&"_"&TEXT(DATE(2026,6,15),"yyyymmdd"),CHI_TIET_CHAM_CONG!$T:$U,2,FALSE()),"") -> P | U9: =IFERROR(VLOOKUP($B9&"_"&TEXT(DATE(2026,6,16),"yyyymmdd"),CHI_TIET_CHAM_CONG!$T:$U,2,FALSE()),"") -> P | V9: =IFERROR(VLOOKUP($B9&"_"&TEXT(DATE(2026,6,17),"yyyymmdd"),CHI_TIET_CHAM_CONG!$T:$U,2,FALSE()),"") -> P | W9: =IFERROR(VLOOKUP($B9&"_"&TEXT(DATE(2026,6,18),"yyyymmdd"),CHI_TIET_CHAM_CONG!$T:$U,2,FALSE()),"") -> P | X9: =IFERROR(VLOOKUP($B9&"_"&TEXT(DATE(2026,6,19),"yyyymmdd"),CHI_TIET_CHAM_CONG!$T:$U,2,FALSE()),"") -> L | Y9: =IFERROR(VLOOKUP($B9&"_"&TEXT(DATE(2026,6,20),"yyyymmdd"),CHI_TIET_CHAM_CONG!$T:$U,2,FALSE()),"") -> L | Z9: CN | AA9: =IFERROR(VLOOKUP($B9&"_"&TEXT(DATE(2026,6,22),"yyyymmdd"),CHI_TIET_CHAM_CONG!$T:$U,2,FALSE()),"") -> P | AB9: =IFERROR(VLOOKUP($B9&"_"&TEXT(DATE(2026,6,23),"yyyymmdd"),CHI_TIET_CHAM_CONG!$T:$U,2,FALSE()),"") -> A | AC9: =IFERROR(VLOOKUP($B9&"_"&TEXT(DATE(2026,6,24),"yyyymmdd"),CHI_TIET_CHAM_CONG!$T:$U,2,FALSE()),"") -> L | AD9: =IFERROR(VLOOKUP($B9&"_"&TEXT(DATE(2026,6,25),"yyyymmdd"),CHI_TIET_CHAM_CONG!$T:$U,2,FALSE()),"") -> P | AE9: =IFERROR(VLOOKUP($B9&"_"&TEXT(DATE(2026,6,26),"yyyymmdd"),CHI_TIET_CHAM_CONG!$T:$U,2,FALSE()),"") -> P | AF9: =IFERROR(VLOOKUP($B9&"_"&TEXT(DATE(2026,6,27),"yyyymmdd"),CHI_TIET_CHAM_CONG!$T:$U,2,FALSE()),"") -> P | AG9: CN | AH9: =IFERROR(VLOOKUP($B9&"_"&TEXT(DATE(2026,6,29),"yyyymmdd"),CHI_TIET_CHAM_CONG!$T:$U,2,FALSE()),"") -> P | AI9: =IFERROR(VLOOKUP($B9&"_"&TEXT(DATE(2026,6,30),"yyyymmdd"),CHI_TIET_CHAM_CONG!$T:$U,2,FALSE()),"") -> P | AJ9: =COUNTIF(F9:AI9,"P")+COUNTIF(F9:AI9,"L") -> 24 | AK9: =COUNTIF(F9:AI9,"L") -> 4 | AL9: =COUNTIF(F9:AI9,"A") -> 1 | AM9: =COUNTIF(F9:AI9,"NP")+COUNTIF(F9:AI9,"KL") -> 1 | AN9: =SUMIF(CHI_TIET_CHAM_CONG!$B:$B,$B9,CHI_TIET_CHAM_CONG!$Q:$Q) -> 4.5
